Workbook

Sheet Pegar
A1: PEGAR AQUÍ (columna A, desde A3): todas las tiras juntas | B1: Nº tira | D1: Pegá todo de una vez en A3. Cada línea cae en una fila y la hoja 'Extractor MT' arma sola una fila por tira.
A2: (fila de apoyo, no borrar) | D2: Antes de pegar nuevas tiras, borrá las anteriores (seleccioná A3:A1002 y Supr).
A3: -1809 1809 4.52 D2323 001 10002 MT262610076000010000247 | B3: =IF(AND(TRIM(A3)<>"",ISNUMBER(FIND(" MT"," "&A3)),LEFT(A3,5)<>"DESC="),MAX(B$2:B2)+1,"") -> 1
A4: DESC=FACEBK *A3UD482JP4 MENLO PARK CA AUTH=R45349 | B4: =IF(AND(TRIM(A4)<>"",ISNUMBER(FIND(" MT"," "&A4)),LEFT(A4,5)<>"DESC="),MAX(B$2:B3)+1,"")
A5: -1809 1809 0.00 D2323 001 10002 MT262610076000010000248 | B5: =IF(AND(TRIM(A5)<>"",ISNUMBER(FIND(" MT"," "&A5)),LEFT(A5,5)<>"DESC="),MAX(B$2:B4)+1,"") -> 2
A6: DESC=TEST | B6: =IF(AND(TRIM(A6)<>"",ISNUMBER(FIND(" MT"," "&A6)),LEFT(A6,5)<>"DESC="),MAX(B$2:B5)+1,"")
A7: -1809 1809 D2323 001 10002 MT262610076000010000249 | B7: =IF(AND(TRIM(A7)<>"",ISNUMBER(FIND(" MT"," "&A7)),LEFT(A7,5)<>"DESC="),MAX(B$2:B6)+1,"") -> 3
A8: DESC=SIN IMPORTE | B8: =IF(AND(TRIM(A8)<>"",ISNUMBER(FIND(" MT"," "&A8)),LEFT(A8,5)<>"DESC="),MAX(B$2:B7)+1,"")
B9: =IF(AND(TRIM(A9)<>"",ISNUMBER(FIND(" MT"," "&A9)),LEFT(A9,5)<>"DESC="),MAX(B$2:B8)+1,"")
B10: =IF(AND(TRIM(A10)<>"",ISNUMBER(FIND(" MT"," "&A10)),LEFT(A10,5)<>"DESC="),MAX(B$2:B9)+1,"")
B11: =IF(AND(TRIM(A11)<>"",ISNUMBER(FIND(" MT"," "&A11)),LEFT(A11,5)<>"DESC="),MAX(B$2:B10)+1,"")
B12: =IF(AND(TRIM(A12)<>"",ISNUMBER(FIND(" MT"," "&A12)),LEFT(A12,5)<>"DESC="),MAX(B$2:B11)+1,"")
B13: =IF(AND(TRIM(A13)<>"",ISNUMBER(FIND(" MT"," "&A13)),LEFT(A13,5)<>"DESC="),MAX(B$2:B12)+1,"")
B14: =IF(AND(TRIM(A14)<>"",ISNUMBER(FIND(" MT"," "&A14)),LEFT(A14,5)<>"DESC="),MAX(B$2:B13)+1,"")
B15: =IF(AND(TRIM(A15)<>"",ISNUMBER(FIND(" MT"," "&A15)),LEFT(A15,5)<>"DESC="),MAX(B$2:B14)+1,"")
B16: =IF(AND(TRIM(A16)<>"",ISNUMBER(FIND(" MT"," "&A16)),LEFT(A16,5)<>"DESC="),MAX(B$2:B15)+1,"")
B17: =IF(AND(TRIM(A17)<>"",ISNUMBER(FIND(" MT"," "&A17)),LEFT(A17,5)<>"DESC="),MAX(B$2:B16)+1,"")
B18: =IF(AND(TRIM(A18)<>"",ISNUMBER(FIND(" MT"," "&A18)),LEFT(A18,5)<>"DESC="),MAX(B$2:B17)+1,"")
B19: =IF(AND(TRIM(A19)<>"",ISNUMBER(FIND(" MT"," "&A19)),LEFT(A19,5)<>"DESC="),MAX(B$2:B18)+1,"")
B20: =IF(AND(TRIM(A20)<>"",ISNUMBER(FIND(" MT"," "&A20)),LEFT(A20,5)<>"DESC="),MAX(B$2:B19)+1,"")
... B1002: =IF(AND(TRIM(A1002)<>"",ISNUMBER(FIND(" MT"," "&A1002)),LEFT(A1002,5)<>"DESC="),MAX(B$2:B1001)+1,"")

Sheet Extractor MT
A1: Extractor de MT: pegá la tira completa y obtené solo el MT
A2: Esta hoja se llena sola: pegá las tiras en la hoja 'Pegar'. Acá no hay que escribir nada.
A4: Tira de la transacción (automática) | B4: MT | C4: ¿Tiene importe? | D4: Importe detectado | F4: Supuesto: el importe es el número con punto decimal (ej. 4.52) de la primera línea de la tira. Tiene importe = VERDADERO si existe y es distinto de 0.
A5: =IFERROR(INDEX(Pegar!$A$3:$A$1002,MATCH(1,Pegar!$B$3:$B$1002,0))&IF(LEFT(INDEX(Pegar!$A$3:$A$1003,MATCH(1,Pegar!$B$3:$B$1002,0)+1),5)="DESC=",CHAR(10)&INDEX(Pegar!$A$3:$A$1003,MATCH(1,Pegar!$B$3:$B$1002,0)+1),""),"") -> -1809 1809 4.52 D2323 001 10002 MT262610076000010000247 DESC=FACEBK *A3UD482JP4 MENLO PARK CA AUTH=R45349 | B5: =IF(TRIM(A5)="","",IFERROR(MID(SUBSTITUTE(SUBSTITUTE(A5,CHAR(10)," "),CHAR(13)," "),FIND(" MT"," "&SUBSTITUTE(SUBSTITUTE(A5,CHAR(10)," "),CHAR(13)," ")),FIND(" ",SUBSTITUTE(SUBSTITUTE(A5,CHAR(10)," "),CHAR(13)," ")&" ",FIND(" MT"," "&SUBSTITUTE(SUBSTITUTE(A5,CHAR(10)," "),CHAR(13)," ")))-FIND(" MT"," "&SUBSTITUTE(SUBSTITUTE(A5,CHAR(10)," "),CHAR(13)," "))),"MT no encontrado")) -> MT262610076000010000247 | C5: =IF(TRIM(A5)="","",IF(D5="",FALSE(),SUBSTITUTE(SUBSTITUTE(SUBSTITUTE(D5,".",""),"0",""),"-","")<>"")) -> TRUE | D5: =IF(TRIM(A5)="","",IFERROR(MID((" "&LEFT(SUBSTITUTE(A5,CHAR(13),""),FIND(CHAR(10),SUBSTITUTE(A5,CHAR(13),"")&CHAR(10))-1)),(FIND("~",SUBSTITUTE(LEFT((" "&LEFT(SUBSTITUTE(A5,CHAR(13),""),FIND(CHAR(10),SUBSTITUTE(A5,CHAR(13),"")&CHAR(10))-1)),FIND(".",(" "&LEFT(SUBSTITUTE(A5,CHAR(13),""),FIND(CHAR(10),SUBSTITUTE(A5,CHAR(13),"")&CHAR(10))-1))))," ","~",LEN(LEFT((" "&LEFT(SUBSTITUTE(A5,CHAR(13),""),FIND(CHAR(10),SUBSTITUTE(A5,CHAR(13),"")&CHAR(10))-1)),FIND(".",(" "&LEFT(SUBSTITUTE(A5,CHAR(13),""),FIND(CHAR(10),SUBSTITUTE(A5,CHAR(13),"")&CHAR(10))-1)))))-LEN(SUBSTITUTE(LEFT((" "&LEFT(SUBSTITUTE(A5,CHAR(13),""),FIND(CHAR(10),SUBSTITUTE(A5,CHAR(13),"")&CHAR(10))-1)),FIND(".",(" "&LEFT(SUBSTITUTE(A5,CHAR(13),""),FIND(CHAR(10),SUBSTITUTE(A5,CHAR(13),"")&CHAR(10))-1))))," ",""))))+1),FIND(" ",(" "&LEFT(SUBSTITUTE(A5,CHAR(13),""),FIND(CHAR(10),SUBSTITUTE(A5,CHAR(13),"")&CHAR(10))-1))&" ",FIND(".",(" "&LEFT(SUBSTITUTE(A5,CHAR(13),""),FIND(CHAR(10),SUBSTITUTE(A5,CHAR(13),"")&CHAR(10))-1))))-(FIND("~",SUBSTITUTE(LEFT((" "&LEFT(SUBSTITUTE(A5,CHAR(13),""),FIND(CHAR(10),SUBSTITUTE(A5,CHAR(13),"")&CHAR(10))-1)),FIND(".",(" "&LEFT(SUBSTITUTE(A5,CHAR(13),""),FIND(CHAR(10),SUBSTITUTE(A5,CHAR(13),"")&CHAR(10))-1))))," ","~",LEN(LEFT((" "&LEFT(SUBSTITUTE(A5,CHAR(13),""),FIND(CHAR(10),SUBSTITUTE(A5,CHAR(13),"")&CHAR(10))-1)),FIND(".",(" "&LEFT(SUBSTITUTE(A5,CHAR(13),""),FIND(CHAR(10),SUBSTITUTE(A5,CHAR(13),"")&CHAR(10))-1)))))-LEN(SUBSTITUTE(LEFT((" "&LEFT(SUBSTITUTE(A5,CHAR(13),""),FIND(CHAR(10),SUBSTITUTE(A5,CHAR(13),"")&CHAR(10))-1)),FIND(".",(" "&LEFT(SUBSTITUTE(A5,CHAR(13),""),FIND(CHAR(10),SUBSTITUTE(A5,CHAR(13),"")&CHAR(10))-1))))," ",""))))+1)),"")) -> 4.52 | F5: La columna D muestra el número que se tomó como importe, para que verifiques.
A6: =IFERROR(INDEX(Pegar!$A$3:$A$1002,MATCH(2,Pegar!$B$3:$B$1002,0))&IF(LEFT(INDEX(Pegar!$A$3:$A$1003,MATCH(2,Pegar!$B$3:$B$1002,0)+1),5)="DESC=",CHAR(10)&INDEX(Pegar!$A$3:$A$1003,MATCH(2,Pegar!$B$3:$B$1002,0)+1),""),"") -> -1809 1809 0.00 D2323 001 10002 MT262610076000010000248 DESC=TEST | B6: =IF(TRIM(A6)="","",IFERROR(MID(SUBSTITUTE(SUBSTITUTE(A6,CHAR(10)," "),CHAR(13)," "),FIND(" MT"," "&SUBSTITUTE(SUBSTITUTE(A6,CHAR(10)," "),CHAR(13)," ")),FIND(" ",SUBSTITUTE(SUBSTITUTE(A6,CHAR(10)," "),CHAR(13)," ")&" ",FIND(" MT"," "&SUBSTITUTE(SUBSTITUTE(A6,CHAR(10)," "),CHAR(13)," ")))-FIND(" MT"," "&SUBSTITUTE(SUBSTITUTE(A6,CHAR(10)," "),CHAR(13)," "))),"MT no encontrado")) -> MT262610076000010000248 | C6: =IF(TRIM(A6)="","",IF(D6="",FALSE(),SUBSTITUTE(SUBSTITUTE(SUBSTITUTE(D6,".",""),"0",""),"-","")<>"")) -> FALSE | D6: =IF(TRIM(A6)="","",IFERROR(MID((" "&LEFT(SUBSTITUTE(A6,CHAR(13),""),FIND(CHAR(10),SUBSTITUTE(A6,CHAR(13),"")&CHAR(10))-1)),(FIND("~",SUBSTITUTE(LEFT((" "&LEFT(SUBSTITUTE(A6,CHAR(13),""),FIND(CHAR(10),SUBSTITUTE(A6,CHAR(13),"")&CHAR(10))-1)),FIND(".",(" "&LEFT(SUBSTITUTE(A6,CHAR(13),""),FIND(CHAR(10),SUBSTITUTE(A6,CHAR(13),"")&CHAR(10))-1))))," ","~",LEN(LEFT((" "&LEFT(SUBSTITUTE(A6,CHAR(13),""),FIND(CHAR(10),SUBSTITUTE(A6,CHAR(13),"")&CHAR(10))-1)),FIND(".",(" "&LEFT(SUBSTITUTE(A6,CHAR(13),""),FIND(CHAR(10),SUBSTITUTE(A6,CHAR(13),"")&CHAR(10))-1)))))-LEN(SUBSTITUTE(LEFT((" "&LEFT(SUBSTITUTE(A6,CHAR(13),""),FIND(CHAR(10),SUBSTITUTE(A6,CHAR(13),"")&CHAR(10))-1)),FIND(".",(" "&LEFT(SUBSTITUTE(A6,CHAR(13),""),FIND(CHAR(10),SUBSTITUTE(A6,CHAR(13),"")&CHAR(10))-1))))," ",""))))+1),FIND(" ",(" "&LEFT(SUBSTITUTE(A6,CHAR(13),""),FIND(CHAR(10),SUBSTITUTE(A6,CHAR(13),"")&CHAR(10))-1))&" ",FIND(".",(" "&LEFT(SUBSTITUTE(A6,CHAR(13),""),FIND(CHAR(10),SUBSTITUTE(A6,CHAR(13),"")&CHAR(10))-1))))-(FIND("~",SUBSTITUTE(LEFT((" "&LEFT(SUBSTITUTE(A6,CHAR(13),""),FIND(CHAR(10),SUBSTITUTE(A6,CHAR(13),"")&CHAR(10))-1)),FIND(".",(" "&LEFT(SUBSTITUTE(A6,CHAR(13),""),FIND(CHAR(10),SUBSTITUTE(A6,CHAR(13),"")&CHAR(10))-1))))," ","~",LEN(LEFT((" "&LEFT(SUBSTITUTE(A6,CHAR(13),""),FIND(CHAR(10),SUBSTITUTE(A6,CHAR(13),"")&CHAR(10))-1)),FIND(".",(" "&LEFT(SUBSTITUTE(A6,CHAR(13),""),FIND(CHAR(10),SUBSTITUTE(A6,CHAR(13),"")&CHAR(10))-1)))))-LEN(SUBSTITUTE(LEFT((" "&LEFT(SUBSTITUTE(A6,CHAR(13),""),FIND(CHAR(10),SUBSTITUTE(A6,CHAR(13),"")&CHAR(10))-1)),FIND(".",(" "&LEFT(SUBSTITUTE(A6,CHAR(13),""),FIND(CHAR(10),SUBSTITUTE(A6,CHAR(13),"")&CHAR(10))-1))))," ",""))))+1)),"")) -> 0.00
A7: =IFERROR(INDEX(Pegar!$A$3:$A$1002,MATCH(3,Pegar!$B$3:$B$1002,0))&IF(LEFT(INDEX(Pegar!$A$3:$A$1003,MATCH(3,Pegar!$B$3:$B$1002,0)+1),5)="DESC=",CHAR(10)&INDEX(Pegar!$A$3:$A$1003,MATCH(3,Pegar!$B$3:$B$1002,0)+1),""),"") -> -1809 1809 D2323 001 10002 MT262610076000010000249 DESC=SIN IMPORTE | B7: =IF(TRIM(A7)="","",IFERROR(MID(SUBSTITUTE(SUBSTITUTE(A7,CHAR(10)," "),CHAR(13)," "),FIND(" MT"," "&SUBSTITUTE(SUBSTITUTE(A7,CHAR(10)," "),CHAR(13)," ")),FIND(" ",SUBSTITUTE(SUBSTITUTE(A7,CHAR(10)," "),CHAR(13)," ")&" ",FIND(" MT"," "&SUBSTITUTE(SUBSTITUTE(A7,CHAR(10)," "),CHAR(13)," ")))-FIND(" MT"," "&SUBSTITUTE(SUBSTITUTE(A7,CHAR(10)," "),CHAR(13)," "))),"MT no encontrado")) -> MT262610076000010000249 | C7: =IF(TRIM(A7)="","",IF(D7="",FALSE(),SUBSTITUTE(SUBSTITUTE(SUBSTITUTE(D7,".",""),"0",""),"-","")<>"")) -> FALSE | D7: =IF(TRIM(A7)="","",IFERROR(MID((" "&LEFT(SUBSTITUTE(A7,CHAR(13),""),FIND(CHAR(10),SUBSTITUTE(A7,CHAR(13),"")&CHAR(10))-1)),(FIND("~",SUBSTITUTE(LEFT((" "&LEFT(SUBSTITUTE(A7,CHAR(13),""),FIND(CHAR(10),SUBSTITUTE(A7,CHAR(13),"")&CHAR(10))-1)),FIND(".",(" "&LEFT(SUBSTITUTE(A7,CHAR(13),""),FIND(CHAR(10),SUBSTITUTE(A7,CHAR(13),"")&CHAR(10))-1))))," ","~",LEN(LEFT((" "&LEFT(SUBSTITUTE(A7,CHAR(13),""),FIND(CHAR(10),SUBSTITUTE(A7,CHAR(13),"")&CHAR(10))-1)),FIND(".",(" "&LEFT(SUBSTITUTE(A7,CHAR(13),""),FIND(CHAR(10),SUBSTITUTE(A7,CHAR(13),"")&CHAR(10))-1)))))-LEN(SUBSTITUTE(LEFT((" "&LEFT(SUBSTITUTE(A7,CHAR(13),""),FIND(CHAR(10),SUBSTITUTE(A7,CHAR(13),"")&CHAR(10))-1)),FIND(".",(" "&LEFT(SUBSTITUTE(A7,CHAR(13),""),FIND(CHAR(10),SUBSTITUTE(A7,CHAR(13),"")&CHAR(10))-1))))," ",""))))+1),FIND(" ",(" "&LEFT(SUBSTITUTE(A7,CHAR(13),""),FIND(CHAR(10),SUBSTITUTE(A7,CHAR(13),"")&CHAR(10))-1))&" ",FIND(".",(" "&LEFT(SUBSTITUTE(A7,CHAR(13),""),FIND(CHAR(10),SUBSTITUTE(A7,CHAR(13),"")&CHAR(10))-1))))-(FIND("~",SUBSTITUTE(LEFT((" "&LEFT(SUBSTITUTE(A7,CHAR(13),""),FIND(CHAR(10),SUBSTITUTE(A7,CHAR(13),"")&CHAR(10))-1)),FIND(".",(" "&LEFT(SUBSTITUTE(A7,CHAR(13),""),FIND(CHAR(10),SUBSTITUTE(A7,CHAR(13),"")&CHAR(10))-1))))," ","~",LEN(LEFT((" "&LEFT(SUBSTITUTE(A7,CHAR(13),""),FIND(CHAR(10),SUBSTITUTE(A7,CHAR(13),"")&CHAR(10))-1)),FIND(".",(" "&LEFT(SUBSTITUTE(A7,CHAR(13),""),FIND(CHAR(10),SUBSTITUTE(A7,CHAR(13),"")&CHAR(10))-1)))))-LEN(SUBSTITUTE(LEFT((" "&LEFT(SUBSTITUTE(A7,CHAR(13),""),FIND(CHAR(10),SUBSTITUTE(A7,CHAR(13),"")&CHAR(10))-1)),FIND(".",(" "&LEFT(SUBSTITUTE(A7,CHAR(13),""),FIND(CHAR(10),SUBSTITUTE(A7,CHAR(13),"")&CHAR(10))-1))))," ",""))))+1)),""))
A8: =IFERROR(INDEX(Pegar!$A$3:$A$1002,MATCH(4,Pegar!$B$3:$B$1002,0))&IF(LEFT(INDEX(Pegar!$A$3:$A$1003,MATCH(4,Pegar!$B$3:$B$1002,0)+1),5)="DESC=",CHAR(10)&INDEX(Pegar!$A$3:$A$1003,MATCH(4,Pegar!$B$3:$B$1002,0)+1),""),"") | B8: =IF(TRIM(A8)="","",IFERROR(MID(SUBSTITUTE(SUBSTITUTE(A8,CHAR(10)," "),CHAR(13)," "),FIND(" MT"," "&SUBSTITUTE(SUBSTITUTE(A8,CHAR(10)," "),CHAR(13)," ")),FIND(" ",SUBSTITUTE(SUBSTITUTE(A8,CHAR(10)," "),CHAR(13)," ")&" ",FIND(" MT"," "&SUBSTITUTE(SUBSTITUTE(A8,CHAR(10)," "),CHAR(13)," ")))-FIND(" MT"," "&SUBSTITUTE(SUBSTITUTE(A8,CHAR(10)," "),CHAR(13)," "))),"MT no encontrado")) | C8: =IF(TRIM(A8)="","",IF(D8="",FALSE(),SUBSTITUTE(SUBSTITUTE(SUBSTITUTE(D8,".",""),"0",""),"-","")<>"")) | D8: =IF(TRIM(A8)="","",IFERROR(MID((" "&LEFT(SUBSTITUTE(A8,CHAR(13),""),FIND(CHAR(10),SUBSTITUTE(A8,CHAR(13),"")&CHAR(10))-1)),(FIND("~",SUBSTITUTE(LEFT((" "&LEFT(SUBSTITUTE(A8,CHAR(13),""),FIND(CHAR(10),SUBSTITUTE(A8,CHAR(13),"")&CHAR(10))-1)),FIND(".",(" "&LEFT(SUBSTITUTE(A8,CHAR(13),""),FIND(CHAR(10),SUBSTITUTE(A8,CHAR(13),"")&CHAR(10))-1))))," ","~",LEN(LEFT((" "&LEFT(SUBSTITUTE(A8,CHAR(13),""),FIND(CHAR(10),SUBSTITUTE(A8,CHAR(13),"")&CHAR(10))-1)),FIND(".",(" "&LEFT(SUBSTITUTE(A8,CHAR(13),""),FIND(CHAR(10),SUBSTITUTE(A8,CHAR(13),"")&CHAR(10))-1)))))-LEN(SUBSTITUTE(LEFT((" "&LEFT(SUBSTITUTE(A8,CHAR(13),""),FIND(CHAR(10),SUBSTITUTE(A8,CHAR(13),"")&CHAR(10))-1)),FIND(".",(" "&LEFT(SUBSTITUTE(A8,CHAR(13),""),FIND(CHAR(10),SUBSTITUTE(A8,CHAR(13),"")&CHAR(10))-1))))," ",""))))+1),FIND(" ",(" "&LEFT(SUBSTITUTE(A8,CHAR(13),""),FIND(CHAR(10),SUBSTITUTE(A8,CHAR(13),"")&CHAR(10))-1))&" ",FIND(".",(" "&LEFT(SUBSTITUTE(A8,CHAR(13),""),FIND(CHAR(10),SUBSTITUTE(A8,CHAR(13),"")&CHAR(10))-1))))-(FIND("~",SUBSTITUTE(LEFT((" "&LEFT(SUBSTITUTE(A8,CHAR(13),""),FIND(CHAR(10),SUBSTITUTE(A8,CHAR(13),"")&CHAR(10))-1)),FIND(".",(" "&LEFT(SUBSTITUTE(A8,CHAR(13),""),FIND(CHAR(10),SUBSTITUTE(A8,CHAR(13),"")&CHAR(10))-1))))," ","~",LEN(LEFT((" "&LEFT(SUBSTITUTE(A8,CHAR(13),""),FIND(CHAR(10),SUBSTITUTE(A8,CHAR(13),"")&CHAR(10))-1)),FIND(".",(" "&LEFT(SUBSTITUTE(A8,CHAR(13),""),FIND(CHAR(10),SUBSTITUTE(A8,CHAR(13),"")&CHAR(10))-1)))))-LEN(SUBSTITUTE(LEFT((" "&LEFT(SUBSTITUTE(A8,CHAR(13),""),FIND(CHAR(10),SUBSTITUTE(A8,CHAR(13),"")&CHAR(10))-1)),FIND(".",(" "&LEFT(SUBSTITUTE(A8,CHAR(13),""),FIND(CHAR(10),SUBSTITUTE(A8,CHAR(13),"")&CHAR(10))-1))))," ",""))))+1)),""))
A9: =IFERROR(INDEX(Pegar!$A$3:$A$1002,MATCH(5,Pegar!$B$3:$B$1002,0))&IF(LEFT(INDEX(Pegar!$A$3:$A$1003,MATCH(5,Pegar!$B$3:$B$1002,0)+1),5)="DESC=",CHAR(10)&INDEX(Pegar!$A$3:$A$1003,MATCH(5,Pegar!$B$3:$B$1002,0)+1),""),"") | B9: =IF(TRIM(A9)="","",IFERROR(MID(SUBSTITUTE(SUBSTITUTE(A9,CHAR(10)," "),CHAR(13)," "),FIND(" MT"," "&SUBSTITUTE(SUBSTITUTE(A9,CHAR(10)," "),CHAR(13)," ")),FIND(" ",SUBSTITUTE(SUBSTITUTE(A9,CHAR(10)," "),CHAR(13)," ")&" ",FIND(" MT"," "&SUBSTITUTE(SUBSTITUTE(A9,CHAR(10)," "),CHAR(13)," ")))-FIND(" MT"," "&SUBSTITUTE(SUBSTITUTE(A9,CHAR(10)," "),CHAR(13)," "))),"MT no encontrado")) | C9: =IF(TRIM(A9)="","",IF(D9="",FALSE(),SUBSTITUTE(SUBSTITUTE(SUBSTITUTE(D9,".",""),"0",""),"-","")<>"")) | D9: =IF(TRIM(A9)="","",IFERROR(MID((" "&LEFT(SUBSTITUTE(A9,CHAR(13),""),FIND(CHAR(10),SUBSTITUTE(A9,CHAR(13),"")&CHAR(10))-1)),(FIND("~",SUBSTITUTE(LEFT((" "&LEFT(SUBSTITUTE(A9,CHAR(13),""),FIND(CHAR(10),SUBSTITUTE(A9,CHAR(13),"")&CHAR(10))-1)),FIND(".",(" "&LEFT(SUBSTITUTE(A9,CHAR(13),""),FIND(CHAR(10),SUBSTITUTE(A9,CHAR(13),"")&CHAR(10))-1))))," ","~",LEN(LEFT((" "&LEFT(SUBSTITUTE(A9,CHAR(13),""),FIND(CHAR(10),SUBSTITUTE(A9,CHAR(13),"")&CHAR(10))-1)),FIND(".",(" "&LEFT(SUBSTITUTE(A9,CHAR(13),""),FIND(CHAR(10),SUBSTITUTE(A9,CHAR(13),"")&CHAR(10))-1)))))-LEN(SUBSTITUTE(LEFT((" "&LEFT(SUBSTITUTE(A9,CHAR(13),""),FIND(CHAR(10),SUBSTITUTE(A9,CHAR(13),"")&CHAR(10))-1)),FIND(".",(" "&LEFT(SUBSTITUTE(A9,CHAR(13),""),FIND(CHAR(10),SUBSTITUTE(A9,CHAR(13),"")&CHAR(10))-1))))," ",""))))+1),FIND(" ",(" "&LEFT(SUBSTITUTE(A9,CHAR(13),""),FIND(CHAR(10),SUBSTITUTE(A9,CHAR(13),"")&CHAR(10))-1))&" ",FIND(".",(" "&LEFT(SUBSTITUTE(A9,CHAR(13),""),FIND(CHAR(10),SUBSTITUTE(A9,CHAR(13),"")&CHAR(10))-1))))-(FIND("~",SUBSTITUTE(LEFT((" "&LEFT(SUBSTITUTE(A9,CHAR(13),""),FIND(CHAR(10),SUBSTITUTE(A9,CHAR(13),"")&CHAR(10))-1)),FIND(".",(" "&LEFT(SUBSTITUTE(A9,CHAR(13),""),FIND(CHAR(10),SUBSTITUTE(A9,CHAR(13),"")&CHAR(10))-1))))," ","~",LEN(LEFT((" "&LEFT(SUBSTITUTE(A9,CHAR(13),""),FIND(CHAR(10),SUBSTITUTE(A9,CHAR(13),"")&CHAR(10))-1)),FIND(".",(" "&LEFT(SUBSTITUTE(A9,CHAR(13),""),FIND(CHAR(10),SUBSTITUTE(A9,CHAR(13),"")&CHAR(10))-1)))))-LEN(SUBSTITUTE(LEFT((" "&LEFT(SUBSTITUTE(A9,CHAR(13),""),FIND(CHAR(10),SUBSTITUTE(A9,CHAR(13),"")&CHAR(10))-1)),FIND(".",(" "&LEFT(SUBSTITUTE(A9,CHAR(13),""),FIND(CHAR(10),SUBSTITUTE(A9,CHAR(13),"")&CHAR(10))-1))))," ",""))))+1)),""))
A10: =IFERROR(INDEX(Pegar!$A$3:$A$1002,MATCH(6,Pegar!$B$3:$B$1002,0))&IF(LEFT(INDEX(Pegar!$A$3:$A$1003,MATCH(6,Pegar!$B$3:$B$1002,0)+1),5)="DESC=",CHAR(10)&INDEX(Pegar!$A$3:$A$1003,MATCH(6,Pegar!$B$3:$B$1002,0)+1),""),"") | B10: =IF(TRIM(A10)="","",IFERROR(MID(SUBSTITUTE(SUBSTITUTE(A10,CHAR(10)," "),CHAR(13)," "),FIND(" MT"," "&SUBSTITUTE(SUBSTITUTE(A10,CHAR(10)," "),CHAR(13)," ")),FIND(" ",SUBSTITUTE(SUBSTITUTE(A10,CHAR(10)," "),CHAR(13)," ")&" ",FIND(" MT"," "&SUBSTITUTE(SUBSTITUTE(A10,CHAR(10)," "),CHAR(13)," ")))-FIND(" MT"," "&SUBSTITUTE(SUBSTITUTE(A10,CHAR(10)," "),CHAR(13)," "))),"MT no encontrado")) | C10: =IF(TRIM(A10)="","",IF(D10="",FALSE(),SUBSTITUTE(SUBSTITUTE(SUBSTITUTE(D10,".",""),"0",""),"-","")<>"")) | D10: =IF(TRIM(A10)="","",IFERROR(MID((" "&LEFT(SUBSTITUTE(A10,CHAR(13),""),FIND(CHAR(10),SUBSTITUTE(A10,CHAR(13),"")&CHAR(10))-1)),(FIND("~",SUBSTITUTE(LEFT((" "&LEFT(SUBSTITUTE(A10,CHAR(13),""),FIND(CHAR(10),SUBSTITUTE(A10,CHAR(13),"")&CHAR(10))-1)),FIND(".",(" "&LEFT(SUBSTITUTE(A10,CHAR(13),""),FIND(CHAR(10),SUBSTITUTE(A10,CHAR(13),"")&CHAR(10))-1))))," ","~",LEN(LEFT((" "&LEFT(SUBSTITUTE(A10,CHAR(13),""),FIND(CHAR(10),SUBSTITUTE(A10,CHAR(13),"")&CHAR(10))-1)),FIND(".",(" "&LEFT(SUBSTITUTE(A10,CHAR(13),""),FIND(CHAR(10),SUBSTITUTE(A10,CHAR(13),"")&CHAR(10))-1)))))-LEN(SUBSTITUTE(LEFT((" "&LEFT(SUBSTITUTE(A10,CHAR(13),""),FIND(CHAR(10),SUBSTITUTE(A10,CHAR(13),"")&CHAR(10))-1)),FIND(".",(" "&LEFT(SUBSTITUTE(A10,CHAR(13),""),FIND(CHAR(10),SUBSTITUTE(A10,CHAR(13),"")&CHAR(10))-1))))," ",""))))+1),FIND(" ",(" "&LEFT(SUBSTITUTE(A10,CHAR(13),""),FIND(CHAR(10),SUBSTITUTE(A10,CHAR(13),"")&CHAR(10))-1))&" ",FIND(".",(" "&LEFT(SUBSTITUTE(A10,CHAR(13),""),FIND(CHAR(10),SUBSTITUTE(A10,CHAR(13),"")&CHAR(10))-1))))-(FIND("~",SUBSTITUTE(LEFT((" "&LEFT(SUBSTITUTE(A10,CHAR(13),""),FIND(CHAR(10),SUBSTITUTE(A10,CHAR(13),"")&CHAR(10))-1)),FIND(".",(" "&LEFT(SUBSTITUTE(A10,CHAR(13),""),FIND(CHAR(10),SUBSTITUTE(A10,CHAR(13),"")&CHAR(10))-1))))," ","~",LEN(LEFT((" "&LEFT(SUBSTITUTE(A10,CHAR(13),""),FIND(CHAR(10),SUBSTITUTE(A10,CHAR(13),"")&CHAR(10))-1)),FIND(".",(" "&LEFT(SUBSTITUTE(A10,CHAR(13),""),FIND(CHAR(10),SUBSTITUTE(A10,CHAR(13),"")&CHAR(10))-1)))))-LEN(SUBSTITUTE(LEFT((" "&LEFT(SUBSTITUTE(A10,CHAR(13),""),FIND(CHAR(10),SUBSTITUTE(A10,CHAR(13),"")&CHAR(10))-1)),FIND(".",(" "&LEFT(SUBSTITUTE(A10,CHAR(13),""),FIND(CHAR(10),SUBSTITUTE(A10,CHAR(13),"")&CHAR(10))-1))))," ",""))))+1)),""))
A11: =IFERROR(INDEX(Pegar!$A$3:$A$1002,MATCH(7,Pegar!$B$3:$B$1002,0))&IF(LEFT(INDEX(Pegar!$A$3:$A$1003,MATCH(7,Pegar!$B$3:$B$1002,0)+1),5)="DESC=",CHAR(10)&INDEX(Pegar!$A$3:$A$1003,MATCH(7,Pegar!$B$3:$B$1002,0)+1),""),"") | B11: =IF(TRIM(A11)="","",IFERROR(MID(SUBSTITUTE(SUBSTITUTE(A11,CHAR(10)," "),CHAR(13)," "),FIND(" MT"," "&SUBSTITUTE(SUBSTITUTE(A11,CHAR(10)," "),CHAR(13)," ")),FIND(" ",SUBSTITUTE(SUBSTITUTE(A11,CHAR(10)," "),CHAR(13)," ")&" ",FIND(" MT"," "&SUBSTITUTE(SUBSTITUTE(A11,CHAR(10)," "),CHAR(13)," ")))-FIND(" MT"," "&SUBSTITUTE(SUBSTITUTE(A11,CHAR(10)," "),CHAR(13)," "))),"MT no encontrado")) | C11: =IF(TRIM(A11)="","",IF(D11="",FALSE(),SUBSTITUTE(SUBSTITUTE(SUBSTITUTE(D11,".",""),"0",""),"-","")<>"")) | D11: =IF(TRIM(A11)="","",IFERROR(MID((" "&LEFT(SUBSTITUTE(A11,CHAR(13),""),FIND(CHAR(10),SUBSTITUTE(A11,CHAR(13),"")&CHAR(10))-1)),(FIND("~",SUBSTITUTE(LEFT((" "&LEFT(SUBSTITUTE(A11,CHAR(13),""),FIND(CHAR(10),SUBSTITUTE(A11,CHAR(13),"")&CHAR(10))-1)),FIND(".",(" "&LEFT(SUBSTITUTE(A11,CHAR(13),""),FIND(CHAR(10),SUBSTITUTE(A11,CHAR(13),"")&CHAR(10))-1))))," ","~",LEN(LEFT((" "&LEFT(SUBSTITUTE(A11,CHAR(13),""),FIND(CHAR(10),SUBSTITUTE(A11,CHAR(13),"")&CHAR(10))-1)),FIND(".",(" "&LEFT(SUBSTITUTE(A11,CHAR(13),""),FIND(CHAR(10),SUBSTITUTE(A11,CHAR(13),"")&CHAR(10))-1)))))-LEN(SUBSTITUTE(LEFT((" "&LEFT(SUBSTITUTE(A11,CHAR(13),""),FIND(CHAR(10),SUBSTITUTE(A11,CHAR(13),"")&CHAR(10))-1)),FIND(".",(" "&LEFT(SUBSTITUTE(A11,CHAR(13),""),FIND(CHAR(10),SUBSTITUTE(A11,CHAR(13),"")&CHAR(10))-1))))," ",""))))+1),FIND(" ",(" "&LEFT(SUBSTITUTE(A11,CHAR(13),""),FIND(CHAR(10),SUBSTITUTE(A11,CHAR(13),"")&CHAR(10))-1))&" ",FIND(".",(" "&LEFT(SUBSTITUTE(A11,CHAR(13),""),FIND(CHAR(10),SUBSTITUTE(A11,CHAR(13),"")&CHAR(10))-1))))-(FIND("~",SUBSTITUTE(LEFT((" "&LEFT(SUBSTITUTE(A11,CHAR(13),""),FIND(CHAR(10),SUBSTITUTE(A11,CHAR(13),"")&CHAR(10))-1)),FIND(".",(" "&LEFT(SUBSTITUTE(A11,CHAR(13),""),FIND(CHAR(10),SUBSTITUTE(A11,CHAR(13),"")&CHAR(10))-1))))," ","~",LEN(LEFT((" "&LEFT(SUBSTITUTE(A11,CHAR(13),""),FIND(CHAR(10),SUBSTITUTE(A11,CHAR(13),"")&CHAR(10))-1)),FIND(".",(" "&LEFT(SUBSTITUTE(A11,CHAR(13),""),FIND(CHAR(10),SUBSTITUTE(A11,CHAR(13),"")&CHAR(10))-1)))))-LEN(SUBSTITUTE(LEFT((" "&LEFT(SUBSTITUTE(A11,CHAR(13),""),FIND(CHAR(10),SUBSTITUTE(A11,CHAR(13),"")&CHAR(10))-1)),FIND(".",(" "&LEFT(SUBSTITUTE(A11,CHAR(13),""),FIND(CHAR(10),SUBSTITUTE(A11,CHAR(13),"")&CHAR(10))-1))))," ",""))))+1)),""))
A12: =IFERROR(INDEX(Pegar!$A$3:$A$1002,MATCH(8,Pegar!$B$3:$B$1002,0))&IF(LEFT(INDEX(Pegar!$A$3:$A$1003,MATCH(8,Pegar!$B$3:$B$1002,0)+1),5)="DESC=",CHAR(10)&INDEX(Pegar!$A$3:$A$1003,MATCH(8,Pegar!$B$3:$B$1002,0)+1),""),"") | B12: =IF(TRIM(A12)="","",IFERROR(MID(SUBSTITUTE(SUBSTITUTE(A12,CHAR(10)," "),CHAR(13)," "),FIND(" MT"," "&SUBSTITUTE(SUBSTITUTE(A12,CHAR(10)," "),CHAR(13)," ")),FIND(" ",SUBSTITUTE(SUBSTITUTE(A12,CHAR(10)," "),CHAR(13)," ")&" ",FIND(" MT"," "&SUBSTITUTE(SUBSTITUTE(A12,CHAR(10)," "),CHAR(13)," ")))-FIND(" MT"," "&SUBSTITUTE(SUBSTITUTE(A12,CHAR(10)," "),CHAR(13)," "))),"MT no encontrado")) | C12: =IF(TRIM(A12)="","",IF(D12="",FALSE(),SUBSTITUTE(SUBSTITUTE(SUBSTITUTE(D12,".",""),"0",""),"-","")<>"")) | D12: =IF(TRIM(A12)="","",IFERROR(MID((" "&LEFT(SUBSTITUTE(A12,CHAR(13),""),FIND(CHAR(10),SUBSTITUTE(A12,CHAR(13),"")&CHAR(10))-1)),(FIND("~",SUBSTITUTE(LEFT((" "&LEFT(SUBSTITUTE(A12,CHAR(13),""),FIND(CHAR(10),SUBSTITUTE(A12,CHAR(13),"")&CHAR(10))-1)),FIND(".",(" "&LEFT(SUBSTITUTE(A12,CHAR(13),""),FIND(CHAR(10),SUBSTITUTE(A12,CHAR(13),"")&CHAR(10))-1))))," ","~",LEN(LEFT((" "&LEFT(SUBSTITUTE(A12,CHAR(13),""),FIND(CHAR(10),SUBSTITUTE(A12,CHAR(13),"")&CHAR(10))-1)),FIND(".",(" "&LEFT(SUBSTITUTE(A12,CHAR(13),""),FIND(CHAR(10),SUBSTITUTE(A12,CHAR(13),"")&CHAR(10))-1)))))-LEN(SUBSTITUTE(LEFT((" "&LEFT(SUBSTITUTE(A12,CHAR(13),""),FIND(CHAR(10),SUBSTITUTE(A12,CHAR(13),"")&CHAR(10))-1)),FIND(".",(" "&LEFT(SUBSTITUTE(A12,CHAR(13),""),FIND(CHAR(10),SUBSTITUTE(A12,CHAR(13),"")&CHAR(10))-1))))," ",""))))+1),FIND(" ",(" "&LEFT(SUBSTITUTE(A12,CHAR(13),""),FIND(CHAR(10),SUBSTITUTE(A12,CHAR(13),"")&CHAR(10))-1))&" ",FIND(".",(" "&LEFT(SUBSTITUTE(A12,CHAR(13),""),FIND(CHAR(10),SUBSTITUTE(A12,CHAR(13),"")&CHAR(10))-1))))-(FIND("~",SUBSTITUTE(LEFT((" "&LEFT(SUBSTITUTE(A12,CHAR(13),""),FIND(CHAR(10),SUBSTITUTE(A12,CHAR(13),"")&CHAR(10))-1)),FIND(".",(" "&LEFT(SUBSTITUTE(A12,CHAR(13),""),FIND(CHAR(10),SUBSTITUTE(A12,CHAR(13),"")&CHAR(10))-1))))," ","~",LEN(LEFT((" "&LEFT(SUBSTITUTE(A12,CHAR(13),""),FIND(CHAR(10),SUBSTITUTE(A12,CHAR(13),"")&CHAR(10))-1)),FIND(".",(" "&LEFT(SUBSTITUTE(A12,CHAR(13),""),FIND(CHAR(10),SUBSTITUTE(A12,CHAR(13),"")&CHAR(10))-1)))))-LEN(SUBSTITUTE(LEFT((" "&LEFT(SUBSTITUTE(A12,CHAR(13),""),FIND(CHAR(10),SUBSTITUTE(A12,CHAR(13),"")&CHAR(10))-1)),FIND(".",(" "&LEFT(SUBSTITUTE(A12,CHAR(13),""),FIND(CHAR(10),SUBSTITUTE(A12,CHAR(13),"")&CHAR(10))-1))))," ",""))))+1)),""))
A13: =IFERROR(INDEX(Pegar!$A$3:$A$1002,MATCH(9,Pegar!$B$3:$B$1002,0))&IF(LEFT(INDEX(Pegar!$A$3:$A$1003,MATCH(9,Pegar!$B$3:$B$1002,0)+1),5)="DESC=",CHAR(10)&INDEX(Pegar!$A$3:$A$1003,MATCH(9,Pegar!$B$3:$B$1002,0)+1),""),"") | B13: =IF(TRIM(A13)="","",IFERROR(MID(SUBSTITUTE(SUBSTITUTE(A13,CHAR(10)," "),CHAR(13)," "),FIND(" MT"," "&SUBSTITUTE(SUBSTITUTE(A13,CHAR(10)," "),CHAR(13)," ")),FIND(" ",SUBSTITUTE(SUBSTITUTE(A13,CHAR(10)," "),CHAR(13)," ")&" ",FIND(" MT"," "&SUBSTITUTE(SUBSTITUTE(A13,CHAR(10)," "),CHAR(13)," ")))-FIND(" MT"," "&SUBSTITUTE(SUBSTITUTE(A13,CHAR(10)," "),CHAR(13)," "))),"MT no encontrado")) | C13: =IF(TRIM(A13)="","",IF(D13="",FALSE(),SUBSTITUTE(SUBSTITUTE(SUBSTITUTE(D13,".",""),"0",""),"-","")<>"")) | D13: =IF(TRIM(A13)="","",IFERROR(MID((" "&LEFT(SUBSTITUTE(A13,CHAR(13),""),FIND(CHAR(10),SUBSTITUTE(A13,CHAR(13),"")&CHAR(10))-1)),(FIND("~",SUBSTITUTE(LEFT((" "&LEFT(SUBSTITUTE(A13,CHAR(13),""),FIND(CHAR(10),SUBSTITUTE(A13,CHAR(13),"")&CHAR(10))-1)),FIND(".",(" "&LEFT(SUBSTITUTE(A13,CHAR(13),""),FIND(CHAR(10),SUBSTITUTE(A13,CHAR(13),"")&CHAR(10))-1))))," ","~",LEN(LEFT((" "&LEFT(SUBSTITUTE(A13,CHAR(13),""),FIND(CHAR(10),SUBSTITUTE(A13,CHAR(13),"")&CHAR(10))-1)),FIND(".",(" "&LEFT(SUBSTITUTE(A13,CHAR(13),""),FIND(CHAR(10),SUBSTITUTE(A13,CHAR(13),"")&CHAR(10))-1)))))-LEN(SUBSTITUTE(LEFT((" "&LEFT(SUBSTITUTE(A13,CHAR(13),""),FIND(CHAR(10),SUBSTITUTE(A13,CHAR(13),"")&CHAR(10))-1)),FIND(".",(" "&LEFT(SUBSTITUTE(A13,CHAR(13),""),FIND(CHAR(10),SUBSTITUTE(A13,CHAR(13),"")&CHAR(10))-1))))," ",""))))+1),FIND(" ",(" "&LEFT(SUBSTITUTE(A13,CHAR(13),""),FIND(CHAR(10),SUBSTITUTE(A13,CHAR(13),"")&CHAR(10))-1))&" ",FIND(".",(" "&LEFT(SUBSTITUTE(A13,CHAR(13),""),FIND(CHAR(10),SUBSTITUTE(A13,CHAR(13),"")&CHAR(10))-1))))-(FIND("~",SUBSTITUTE(LEFT((" "&LEFT(SUBSTITUTE(A13,CHAR(13),""),FIND(CHAR(10),SUBSTITUTE(A13,CHAR(13),"")&CHAR(10))-1)),FIND(".",(" "&LEFT(SUBSTITUTE(A13,CHAR(13),""),FIND(CHAR(10),SUBSTITUTE(A13,CHAR(13),"")&CHAR(10))-1))))," ","~",LEN(LEFT((" "&LEFT(SUBSTITUTE(A13,CHAR(13),""),FIND(CHAR(10),SUBSTITUTE(A13,CHAR(13),"")&CHAR(10))-1)),FIND(".",(" "&LEFT(SUBSTITUTE(A13,CHAR(13),""),FIND(CHAR(10),SUBSTITUTE(A13,CHAR(13),"")&CHAR(10))-1)))))-LEN(SUBSTITUTE(LEFT((" "&LEFT(SUBSTITUTE(A13,CHAR(13),""),FIND(CHAR(10),SUBSTITUTE(A13,CHAR(13),"")&CHAR(10))-1)),FIND(".",(" "&LEFT(SUBSTITUTE(A13,CHAR(13),""),FIND(CHAR(10),SUBSTITUTE(A13,CHAR(13),"")&CHAR(10))-1))))," ",""))))+1)),""))
A14: =IFERROR(INDEX(Pegar!$A$3:$A$1002,MATCH(10,Pegar!$B$3:$B$1002,0))&IF(LEFT(INDEX(Pegar!$A$3:$A$1003,MATCH(10,Pegar!$B$3:$B$1002,0)+1),5)="DESC=",CHAR(10)&INDEX(Pegar!$A$3:$A$1003,MATCH(10,Pegar!$B$3:$B$1002,0)+1),""),"") | B14: =IF(TRIM(A14)="","",IFERROR(MID(SUBSTITUTE(SUBSTITUTE(A14,CHAR(10)," "),CHAR(13)," "),FIND(" MT"," "&SUBSTITUTE(SUBSTITUTE(A14,CHAR(10)," "),CHAR(13)," ")),FIND(" ",SUBSTITUTE(SUBSTITUTE(A14,CHAR(10)," "),CHAR(13)," ")&" ",FIND(" MT"," "&SUBSTITUTE(SUBSTITUTE(A14,CHAR(10)," "),CHAR(13)," ")))-FIND(" MT"," "&SUBSTITUTE(SUBSTITUTE(A14,CHAR(10)," "),CHAR(13)," "))),"MT no encontrado")) | C14: =IF(TRIM(A14)="","",IF(D14="",FALSE(),SUBSTITUTE(SUBSTITUTE(SUBSTITUTE(D14,".",""),"0",""),"-","")<>"")) | D14: =IF(TRIM(A14)="","",IFERROR(MID((" "&LEFT(SUBSTITUTE(A14,CHAR(13),""),FIND(CHAR(10),SUBSTITUTE(A14,CHAR(13),"")&CHAR(10))-1)),(FIND("~",SUBSTITUTE(LEFT((" "&LEFT(SUBSTITUTE(A14,CHAR(13),""),FIND(CHAR(10),SUBSTITUTE(A14,CHAR(13),"")&CHAR(10))-1)),FIND(".",(" "&LEFT(SUBSTITUTE(A14,CHAR(13),""),FIND(CHAR(10),SUBSTITUTE(A14,CHAR(13),"")&CHAR(10))-1))))," ","~",LEN(LEFT((" "&LEFT(SUBSTITUTE(A14,CHAR(13),""),FIND(CHAR(10),SUBSTITUTE(A14,CHAR(13),"")&CHAR(10))-1)),FIND(".",(" "&LEFT(SUBSTITUTE(A14,CHAR(13),""),FIND(CHAR(10),SUBSTITUTE(A14,CHAR(13),"")&CHAR(10))-1)))))-LEN(SUBSTITUTE(LEFT((" "&LEFT(SUBSTITUTE(A14,CHAR(13),""),FIND(CHAR(10),SUBSTITUTE(A14,CHAR(13),"")&CHAR(10))-1)),FIND(".",(" "&LEFT(SUBSTITUTE(A14,CHAR(13),""),FIND(CHAR(10),SUBSTITUTE(A14,CHAR(13),"")&CHAR(10))-1))))," ",""))))+1),FIND(" ",(" "&LEFT(SUBSTITUTE(A14,CHAR(13),""),FIND(CHAR(10),SUBSTITUTE(A14,CHAR(13),"")&CHAR(10))-1))&" ",FIND(".",(" "&LEFT(SUBSTITUTE(A14,CHAR(13),""),FIND(CHAR(10),SUBSTITUTE(A14,CHAR(13),"")&CHAR(10))-1))))-(FIND("~",SUBSTITUTE(LEFT((" "&LEFT(SUBSTITUTE(A14,CHAR(13),""),FIND(CHAR(10),SUBSTITUTE(A14,CHAR(13),"")&CHAR(10))-1)),FIND(".",(" "&LEFT(SUBSTITUTE(A14,CHAR(13),""),FIND(CHAR(10),SUBSTITUTE(A14,CHAR(13),"")&CHAR(10))-1))))," ","~",LEN(LEFT((" "&LEFT(SUBSTITUTE(A14,CHAR(13),""),FIND(CHAR(10),SUBSTITUTE(A14,CHAR(13),"")&CHAR(10))-1)),FIND(".",(" "&LEFT(SUBSTITUTE(A14,CHAR(13),""),FIND(CHAR(10),SUBSTITUTE(A14,CHAR(13),"")&CHAR(10))-1)))))-LEN(SUBSTITUTE(LEFT((" "&LEFT(SUBSTITUTE(A14,CHAR(13),""),FIND(CHAR(10),SUBSTITUTE(A14,CHAR(13),"")&CHAR(10))-1)),FIND(".",(" "&LEFT(SUBSTITUTE(A14,CHAR(13),""),FIND(CHAR(10),SUBSTITUTE(A14,CHAR(13),"")&CHAR(10))-1))))," ",""))))+1)),""))
A15: =IFERROR(INDEX(Pegar!$A$3:$A$1002,MATCH(11,Pegar!$B$3:$B$1002,0))&IF(LEFT(INDEX(Pegar!$A$3:$A$1003,MATCH(11,Pegar!$B$3:$B$1002,0)+1),5)="DESC=",CHAR(10)&INDEX(Pegar!$A$3:$A$1003,MATCH(11,Pegar!$B$3:$B$1002,0)+1),""),"") | B15: =IF(TRIM(A15)="","",IFERROR(MID(SUBSTITUTE(SUBSTITUTE(A15,CHAR(10)," "),CHAR(13)," "),FIND(" MT"," "&SUBSTITUTE(SUBSTITUTE(A15,CHAR(10)," "),CHAR(13)," ")),FIND(" ",SUBSTITUTE(SUBSTITUTE(A15,CHAR(10)," "),CHAR(13)," ")&" ",FIND(" MT"," "&SUBSTITUTE(SUBSTITUTE(A15,CHAR(10)," "),CHAR(13)," ")))-FIND(" MT"," "&SUBSTITUTE(SUBSTITUTE(A15,CHAR(10)," "),CHAR(13)," "))),"MT no encontrado")) | C15: =IF(TRIM(A15)="","",IF(D15="",FALSE(),SUBSTITUTE(SUBSTITUTE(SUBSTITUTE(D15,".",""),"0",""),"-","")<>"")) | D15: =IF(TRIM(A15)="","",IFERROR(MID((" "&LEFT(SUBSTITUTE(A15,CHAR(13),""),FIND(CHAR(10),SUBSTITUTE(A15,CHAR(13),"")&CHAR(10))-1)),(FIND("~",SUBSTITUTE(LEFT((" "&LEFT(SUBSTITUTE(A15,CHAR(13),""),FIND(CHAR(10),SUBSTITUTE(A15,CHAR(13),"")&CHAR(10))-1)),FIND(".",(" "&LEFT(SUBSTITUTE(A15,CHAR(13),""),FIND(CHAR(10),SUBSTITUTE(A15,CHAR(13),"")&CHAR(10))-1))))," ","~",LEN(LEFT((" "&LEFT(SUBSTITUTE(A15,CHAR(13),""),FIND(CHAR(10),SUBSTITUTE(A15,CHAR(13),"")&CHAR(10))-1)),FIND(".",(" "&LEFT(SUBSTITUTE(A15,CHAR(13),""),FIND(CHAR(10),SUBSTITUTE(A15,CHAR(13),"")&CHAR(10))-1)))))-LEN(SUBSTITUTE(LEFT((" "&LEFT(SUBSTITUTE(A15,CHAR(13),""),FIND(CHAR(10),SUBSTITUTE(A15,CHAR(13),"")&CHAR(10))-1)),FIND(".",(" "&LEFT(SUBSTITUTE(A15,CHAR(13),""),FIND(CHAR(10),SUBSTITUTE(A15,CHAR(13),"")&CHAR(10))-1))))," ",""))))+1),FIND(" ",(" "&LEFT(SUBSTITUTE(A15,CHAR(13),""),FIND(CHAR(10),SUBSTITUTE(A15,CHAR(13),"")&CHAR(10))-1))&" ",FIND(".",(" "&LEFT(SUBSTITUTE(A15,CHAR(13),""),FIND(CHAR(10),SUBSTITUTE(A15,CHAR(13),"")&CHAR(10))-1))))-(FIND("~",SUBSTITUTE(LEFT((" "&LEFT(SUBSTITUTE(A15,CHAR(13),""),FIND(CHAR(10),SUBSTITUTE(A15,CHAR(13),"")&CHAR(10))-1)),FIND(".",(" "&LEFT(SUBSTITUTE(A15,CHAR(13),""),FIND(CHAR(10),SUBSTITUTE(A15,CHAR(13),"")&CHAR(10))-1))))," ","~",LEN(LEFT((" "&LEFT(SUBSTITUTE(A15,CHAR(13),""),FIND(CHAR(10),SUBSTITUTE(A15,CHAR(13),"")&CHAR(10))-1)),FIND(".",(" "&LEFT(SUBSTITUTE(A15,CHAR(13),""),FIND(CHAR(10),SUBSTITUTE(A15,CHAR(13),"")&CHAR(10))-1)))))-LEN(SUBSTITUTE(LEFT((" "&LEFT(SUBSTITUTE(A15,CHAR(13),""),FIND(CHAR(10),SUBSTITUTE(A15,CHAR(13),"")&CHAR(10))-1)),FIND(".",(" "&LEFT(SUBSTITUTE(A15,CHAR(13),""),FIND(CHAR(10),SUBSTITUTE(A15,CHAR(13),"")&CHAR(10))-1))))," ",""))))+1)),""))
A16: =IFERROR(INDEX(Pegar!$A$3:$A$1002,MATCH(12,Pegar!$B$3:$B$1002,0))&IF(LEFT(INDEX(Pegar!$A$3:$A$1003,MATCH(12,Pegar!$B$3:$B$1002,0)+1),5)="DESC=",CHAR(10)&INDEX(Pegar!$A$3:$A$1003,MATCH(12,Pegar!$B$3:$B$1002,0)+1),""),"") | B16: =IF(TRIM(A16)="","",IFERROR(MID(SUBSTITUTE(SUBSTITUTE(A16,CHAR(10)," "),CHAR(13)," "),FIND(" MT"," "&SUBSTITUTE(SUBSTITUTE(A16,CHAR(10)," "),CHAR(13)," ")),FIND(" ",SUBSTITUTE(SUBSTITUTE(A16,CHAR(10)," "),CHAR(13)," ")&" ",FIND(" MT"," "&SUBSTITUTE(SUBSTITUTE(A16,CHAR(10)," "),CHAR(13)," ")))-FIND(" MT"," "&SUBSTITUTE(SUBSTITUTE(A16,CHAR(10)," "),CHAR(13)," "))),"MT no encontrado")) | C16: =IF(TRIM(A16)="","",IF(D16="",FALSE(),SUBSTITUTE(SUBSTITUTE(SUBSTITUTE(D16,".",""),"0",""),"-","")<>"")) | D16: =IF(TRIM(A16)="","",IFERROR(MID((" "&LEFT(SUBSTITUTE(A16,CHAR(13),""),FIND(CHAR(10),SUBSTITUTE(A16,CHAR(13),"")&CHAR(10))-1)),(FIND("~",SUBSTITUTE(LEFT((" "&LEFT(SUBSTITUTE(A16,CHAR(13),""),FIND(CHAR(10),SUBSTITUTE(A16,CHAR(13),"")&CHAR(10))-1)),FIND(".",(" "&LEFT(SUBSTITUTE(A16,CHAR(13),""),FIND(CHAR(10),SUBSTITUTE(A16,CHAR(13),"")&CHAR(10))-1))))," ","~",LEN(LEFT((" "&LEFT(SUBSTITUTE(A16,CHAR(13),""),FIND(CHAR(10),SUBSTITUTE(A16,CHAR(13),"")&CHAR(10))-1)),FIND(".",(" "&LEFT(SUBSTITUTE(A16,CHAR(13),""),FIND(CHAR(10),SUBSTITUTE(A16,CHAR(13),"")&CHAR(10))-1)))))-LEN(SUBSTITUTE(LEFT((" "&LEFT(SUBSTITUTE(A16,CHAR(13),""),FIND(CHAR(10),SUBSTITUTE(A16,CHAR(13),"")&CHAR(10))-1)),FIND(".",(" "&LEFT(SUBSTITUTE(A16,CHAR(13),""),FIND(CHAR(10),SUBSTITUTE(A16,CHAR(13),"")&CHAR(10))-1))))," ",""))))+1),FIND(" ",(" "&LEFT(SUBSTITUTE(A16,CHAR(13),""),FIND(CHAR(10),SUBSTITUTE(A16,CHAR(13),"")&CHAR(10))-1))&" ",FIND(".",(" "&LEFT(SUBSTITUTE(A16,CHAR(13),""),FIND(CHAR(10),SUBSTITUTE(A16,CHAR(13),"")&CHAR(10))-1))))-(FIND("~",SUBSTITUTE(LEFT((" "&LEFT(SUBSTITUTE(A16,CHAR(13),""),FIND(CHAR(10),SUBSTITUTE(A16,CHAR(13),"")&CHAR(10))-1)),FIND(".",(" "&LEFT(SUBSTITUTE(A16,CHAR(13),""),FIND(CHAR(10),SUBSTITUTE(A16,CHAR(13),"")&CHAR(10))-1))))," ","~",LEN(LEFT((" "&LEFT(SUBSTITUTE(A16,CHAR(13),""),FIND(CHAR(10),SUBSTITUTE(A16,CHAR(13),"")&CHAR(10))-1)),FIND(".",(" "&LEFT(SUBSTITUTE(A16,CHAR(13),""),FIND(CHAR(10),SUBSTITUTE(A16,CHAR(13),"")&CHAR(10))-1)))))-LEN(SUBSTITUTE(LEFT((" "&LEFT(SUBSTITUTE(A16,CHAR(13),""),FIND(CHAR(10),SUBSTITUTE(A16,CHAR(13),"")&CHAR(10))-1)),FIND(".",(" "&LEFT(SUBSTITUTE(A16,CHAR(13),""),FIND(CHAR(10),SUBSTITUTE(A16,CHAR(13),"")&CHAR(10))-1))))," ",""))))+1)),""))
A17: =IFERROR(INDEX(Pegar!$A$3:$A$1002,MATCH(13,Pegar!$B$3:$B$1002,0))&IF(LEFT(INDEX(Pegar!$A$3:$A$1003,MATCH(13,Pegar!$B$3:$B$1002,0)+1),5)="DESC=",CHAR(10)&INDEX(Pegar!$A$3:$A$1003,MATCH(13,Pegar!$B$3:$B$1002,0)+1),""),"") | B17: =IF(TRIM(A17)="","",IFERROR(MID(SUBSTITUTE(SUBSTITUTE(A17,CHAR(10)," "),CHAR(13)," "),FIND(" MT"," "&SUBSTITUTE(SUBSTITUTE(A17,CHAR(10)," "),CHAR(13)," ")),FIND(" ",SUBSTITUTE(SUBSTITUTE(A17,CHAR(10)," "),CHAR(13)," ")&" ",FIND(" MT"," "&SUBSTITUTE(SUBSTITUTE(A17,CHAR(10)," "),CHAR(13)," ")))-FIND(" MT"," "&SUBSTITUTE(SUBSTITUTE(A17,CHAR(10)," "),CHAR(13)," "))),"MT no encontrado")) | C17: =IF(TRIM(A17)="","",IF(D17="",FALSE(),SUBSTITUTE(SUBSTITUTE(SUBSTITUTE(D17,".",""),"0",""),"-","")<>"")) | D17: =IF(TRIM(A17)="","",IFERROR(MID((" "&LEFT(SUBSTITUTE(A17,CHAR(13),""),FIND(CHAR(10),SUBSTITUTE(A17,CHAR(13),"")&CHAR(10))-1)),(FIND("~",SUBSTITUTE(LEFT((" "&LEFT(SUBSTITUTE(A17,CHAR(13),""),FIND(CHAR(10),SUBSTITUTE(A17,CHAR(13),"")&CHAR(10))-1)),FIND(".",(" "&LEFT(SUBSTITUTE(A17,CHAR(13),""),FIND(CHAR(10),SUBSTITUTE(A17,CHAR(13),"")&CHAR(10))-1))))," ","~",LEN(LEFT((" "&LEFT(SUBSTITUTE(A17,CHAR(13),""),FIND(CHAR(10),SUBSTITUTE(A17,CHAR(13),"")&CHAR(10))-1)),FIND(".",(" "&LEFT(SUBSTITUTE(A17,CHAR(13),""),FIND(CHAR(10),SUBSTITUTE(A17,CHAR(13),"")&CHAR(10))-1)))))-LEN(SUBSTITUTE(LEFT((" "&LEFT(SUBSTITUTE(A17,CHAR(13),""),FIND(CHAR(10),SUBSTITUTE(A17,CHAR(13),"")&CHAR(10))-1)),FIND(".",(" "&LEFT(SUBSTITUTE(A17,CHAR(13),""),FIND(CHAR(10),SUBSTITUTE(A17,CHAR(13),"")&CHAR(10))-1))))," ",""))))+1),FIND(" ",(" "&LEFT(SUBSTITUTE(A17,CHAR(13),""),FIND(CHAR(10),SUBSTITUTE(A17,CHAR(13),"")&CHAR(10))-1))&" ",FIND(".",(" "&LEFT(SUBSTITUTE(A17,CHAR(13),""),FIND(CHAR(10),SUBSTITUTE(A17,CHAR(13),"")&CHAR(10))-1))))-(FIND("~",SUBSTITUTE(LEFT((" "&LEFT(SUBSTITUTE(A17,CHAR(13),""),FIND(CHAR(10),SUBSTITUTE(A17,CHAR(13),"")&CHAR(10))-1)),FIND(".",(" "&LEFT(SUBSTITUTE(A17,CHAR(13),""),FIND(CHAR(10),SUBSTITUTE(A17,CHAR(13),"")&CHAR(10))-1))))," ","~",LEN(LEFT((" "&LEFT(SUBSTITUTE(A17,CHAR(13),""),FIND(CHAR(10),SUBSTITUTE(A17,CHAR(13),"")&CHAR(10))-1)),FIND(".",(" "&LEFT(SUBSTITUTE(A17,CHAR(13),""),FIND(CHAR(10),SUBSTITUTE(A17,CHAR(13),"")&CHAR(10))-1)))))-LEN(SUBSTITUTE(LEFT((" "&LEFT(SUBSTITUTE(A17,CHAR(13),""),FIND(CHAR(10),SUBSTITUTE(A17,CHAR(13),"")&CHAR(10))-1)),FIND(".",(" "&LEFT(SUBSTITUTE(A17,CHAR(13),""),FIND(CHAR(10),SUBSTITUTE(A17,CHAR(13),"")&CHAR(10))-1))))," ",""))))+1)),""))
A18: =IFERROR(INDEX(Pegar!$A$3:$A$1002,MATCH(14,Pegar!$B$3:$B$1002,0))&IF(LEFT(INDEX(Pegar!$A$3:$A$1003,MATCH(14,Pegar!$B$3:$B$1002,0)+1),5)="DESC=",CHAR(10)&INDEX(Pegar!$A$3:$A$1003,MATCH(14,Pegar!$B$3:$B$1002,0)+1),""),"") | B18: =IF(TRIM(A18)="","",IFERROR(MID(SUBSTITUTE(SUBSTITUTE(A18,CHAR(10)," "),CHAR(13)," "),FIND(" MT"," "&SUBSTITUTE(SUBSTITUTE(A18,CHAR(10)," "),CHAR(13)," ")),FIND(" ",SUBSTITUTE(SUBSTITUTE(A18,CHAR(10)," "),CHAR(13)," ")&" ",FIND(" MT"," "&SUBSTITUTE(SUBSTITUTE(A18,CHAR(10)," "),CHAR(13)," ")))-FIND(" MT"," "&SUBSTITUTE(SUBSTITUTE(A18,CHAR(10)," "),CHAR(13)," "))),"MT no encontrado")) | C18: =IF(TRIM(A18)="","",IF(D18="",FALSE(),SUBSTITUTE(SUBSTITUTE(SUBSTITUTE(D18,".",""),"0",""),"-","")<>"")) | D18: =IF(TRIM(A18)="","",IFERROR(MID((" "&LEFT(SUBSTITUTE(A18,CHAR(13),""),FIND(CHAR(10),SUBSTITUTE(A18,CHAR(13),"")&CHAR(10))-1)),(FIND("~",SUBSTITUTE(LEFT((" "&LEFT(SUBSTITUTE(A18,CHAR(13),""),FIND(CHAR(10),SUBSTITUTE(A18,CHAR(13),"")&CHAR(10))-1)),FIND(".",(" "&LEFT(SUBSTITUTE(A18,CHAR(13),""),FIND(CHAR(10),SUBSTITUTE(A18,CHAR(13),"")&CHAR(10))-1))))," ","~",LEN(LEFT((" "&LEFT(SUBSTITUTE(A18,CHAR(13),""),FIND(CHAR(10),SUBSTITUTE(A18,CHAR(13),"")&CHAR(10))-1)),FIND(".",(" "&LEFT(SUBSTITUTE(A18,CHAR(13),""),FIND(CHAR(10),SUBSTITUTE(A18,CHAR(13),"")&CHAR(10))-1)))))-LEN(SUBSTITUTE(LEFT((" "&LEFT(SUBSTITUTE(A18,CHAR(13),""),FIND(CHAR(10),SUBSTITUTE(A18,CHAR(13),"")&CHAR(10))-1)),FIND(".",(" "&LEFT(SUBSTITUTE(A18,CHAR(13),""),FIND(CHAR(10),SUBSTITUTE(A18,CHAR(13),"")&CHAR(10))-1))))," ",""))))+1),FIND(" ",(" "&LEFT(SUBSTITUTE(A18,CHAR(13),""),FIND(CHAR(10),SUBSTITUTE(A18,CHAR(13),"")&CHAR(10))-1))&" ",FIND(".",(" "&LEFT(SUBSTITUTE(A18,CHAR(13),""),FIND(CHAR(10),SUBSTITUTE(A18,CHAR(13),"")&CHAR(10))-1))))-(FIND("~",SUBSTITUTE(LEFT((" "&LEFT(SUBSTITUTE(A18,CHAR(13),""),FIND(CHAR(10),SUBSTITUTE(A18,CHAR(13),"")&CHAR(10))-1)),FIND(".",(" "&LEFT(SUBSTITUTE(A18,CHAR(13),""),FIND(CHAR(10),SUBSTITUTE(A18,CHAR(13),"")&CHAR(10))-1))))," ","~",LEN(LEFT((" "&LEFT(SUBSTITUTE(A18,CHAR(13),""),FIND(CHAR(10),SUBSTITUTE(A18,CHAR(13),"")&CHAR(10))-1)),FIND(".",(" "&LEFT(SUBSTITUTE(A18,CHAR(13),""),FIND(CHAR(10),SUBSTITUTE(A18,CHAR(13),"")&CHAR(10))-1)))))-LEN(SUBSTITUTE(LEFT((" "&LEFT(SUBSTITUTE(A18,CHAR(13),""),FIND(CHAR(10),SUBSTITUTE(A18,CHAR(13),"")&CHAR(10))-1)),FIND(".",(" "&LEFT(SUBSTITUTE(A18,CHAR(13),""),FIND(CHAR(10),SUBSTITUTE(A18,CHAR(13),"")&CHAR(10))-1))))," ",""))))+1)),""))
A19: =IFERROR(INDEX(Pegar!$A$3:$A$1002,MATCH(15,Pegar!$B$3:$B$1002,0))&IF(LEFT(INDEX(Pegar!$A$3:$A$1003,MATCH(15,Pegar!$B$3:$B$1002,0)+1),5)="DESC=",CHAR(10)&INDEX(Pegar!$A$3:$A$1003,MATCH(15,Pegar!$B$3:$B$1002,0)+1),""),"") | B19: =IF(TRIM(A19)="","",IFERROR(MID(SUBSTITUTE(SUBSTITUTE(A19,CHAR(10)," "),CHAR(13)," "),FIND(" MT"," "&SUBSTITUTE(SUBSTITUTE(A19,CHAR(10)," "),CHAR(13)," ")),FIND(" ",SUBSTITUTE(SUBSTITUTE(A19,CHAR(10)," "),CHAR(13)," ")&" ",FIND(" MT"," "&SUBSTITUTE(SUBSTITUTE(A19,CHAR(10)," "),CHAR(13)," ")))-FIND(" MT"," "&SUBSTITUTE(SUBSTITUTE(A19,CHAR(10)," "),CHAR(13)," "))),"MT no encontrado")) | C19: =IF(TRIM(A19)="","",IF(D19="",FALSE(),SUBSTITUTE(SUBSTITUTE(SUBSTITUTE(D19,".",""),"0",""),"-","")<>"")) | D19: =IF(TRIM(A19)="","",IFERROR(MID((" "&LEFT(SUBSTITUTE(A19,CHAR(13),""),FIND(CHAR(10),SUBSTITUTE(A19,CHAR(13),"")&CHAR(10))-1)),(FIND("~",SUBSTITUTE(LEFT((" "&LEFT(SUBSTITUTE(A19,CHAR(13),""),FIND(CHAR(10),SUBSTITUTE(A19,CHAR(13),"")&CHAR(10))-1)),FIND(".",(" "&LEFT(SUBSTITUTE(A19,CHAR(13),""),FIND(CHAR(10),SUBSTITUTE(A19,CHAR(13),"")&CHAR(10))-1))))," ","~",LEN(LEFT((" "&LEFT(SUBSTITUTE(A19,CHAR(13),""),FIND(CHAR(10),SUBSTITUTE(A19,CHAR(13),"")&CHAR(10))-1)),FIND(".",(" "&LEFT(SUBSTITUTE(A19,CHAR(13),""),FIND(CHAR(10),SUBSTITUTE(A19,CHAR(13),"")&CHAR(10))-1)))))-LEN(SUBSTITUTE(LEFT((" "&LEFT(SUBSTITUTE(A19,CHAR(13),""),FIND(CHAR(10),SUBSTITUTE(A19,CHAR(13),"")&CHAR(10))-1)),FIND(".",(" "&LEFT(SUBSTITUTE(A19,CHAR(13),""),FIND(CHAR(10),SUBSTITUTE(A19,CHAR(13),"")&CHAR(10))-1))))," ",""))))+1),FIND(" ",(" "&LEFT(SUBSTITUTE(A19,CHAR(13),""),FIND(CHAR(10),SUBSTITUTE(A19,CHAR(13),"")&CHAR(10))-1))&" ",FIND(".",(" "&LEFT(SUBSTITUTE(A19,CHAR(13),""),FIND(CHAR(10),SUBSTITUTE(A19,CHAR(13),"")&CHAR(10))-1))))-(FIND("~",SUBSTITUTE(LEFT((" "&LEFT(SUBSTITUTE(A19,CHAR(13),""),FIND(CHAR(10),SUBSTITUTE(A19,CHAR(13),"")&CHAR(10))-1)),FIND(".",(" "&LEFT(SUBSTITUTE(A19,CHAR(13),""),FIND(CHAR(10),SUBSTITUTE(A19,CHAR(13),"")&CHAR(10))-1))))," ","~",LEN(LEFT((" "&LEFT(SUBSTITUTE(A19,CHAR(13),""),FIND(CHAR(10),SUBSTITUTE(A19,CHAR(13),"")&CHAR(10))-1)),FIND(".",(" "&LEFT(SUBSTITUTE(A19,CHAR(13),""),FIND(CHAR(10),SUBSTITUTE(A19,CHAR(13),"")&CHAR(10))-1)))))-LEN(SUBSTITUTE(LEFT((" "&LEFT(SUBSTITUTE(A19,CHAR(13),""),FIND(CHAR(10),SUBSTITUTE(A19,CHAR(13),"")&CHAR(10))-1)),FIND(".",(" "&LEFT(SUBSTITUTE(A19,CHAR(13),""),FIND(CHAR(10),SUBSTITUTE(A19,CHAR(13),"")&CHAR(10))-1))))," ",""))))+1)),""))
A20: =IFERROR(INDEX(Pegar!$A$3:$A$1002,MATCH(16,Pegar!$B$3:$B$1002,0))&IF(LEFT(INDEX(Pegar!$A$3:$A$1003,MATCH(16,Pegar!$B$3:$B$1002,0)+1),5)="DESC=",CHAR(10)&INDEX(Pegar!$A$3:$A$1003,MATCH(16,Pegar!$B$3:$B$1002,0)+1),""),"") | B20: =IF(TRIM(A20)="","",IFERROR(MID(SUBSTITUTE(SUBSTITUTE(A20,CHAR(10)," "),CHAR(13)," "),FIND(" MT"," "&SUBSTITUTE(SUBSTITUTE(A20,CHAR(10)," "),CHAR(13)," ")),FIND(" ",SUBSTITUTE(SUBSTITUTE(A20,CHAR(10)," "),CHAR(13)," ")&" ",FIND(" MT"," "&SUBSTITUTE(SUBSTITUTE(A20,CHAR(10)," "),CHAR(13)," ")))-FIND(" MT"," "&SUBSTITUTE(SUBSTITUTE(A20,CHAR(10)," "),CHAR(13)," "))),"MT no encontrado")) | C20: =IF(TRIM(A20)="","",IF(D20="",FALSE(),SUBSTITUTE(SUBSTITUTE(SUBSTITUTE(D20,".",""),"0",""),"-","")<>"")) | D20: =IF(TRIM(A20)="","",IFERROR(MID((" "&LEFT(SUBSTITUTE(A20,CHAR(13),""),FIND(CHAR(10),SUBSTITUTE(A20,CHAR(13),"")&CHAR(10))-1)),(FIND("~",SUBSTITUTE(LEFT((" "&LEFT(SUBSTITUTE(A20,CHAR(13),""),FIND(CHAR(10),SUBSTITUTE(A20,CHAR(13),"")&CHAR(10))-1)),FIND(".",(" "&LEFT(SUBSTITUTE(A20,CHAR(13),""),FIND(CHAR(10),SUBSTITUTE(A20,CHAR(13),"")&CHAR(10))-1))))," ","~",LEN(LEFT((" "&LEFT(SUBSTITUTE(A20,CHAR(13),""),FIND(CHAR(10),SUBSTITUTE(A20,CHAR(13),"")&CHAR(10))-1)),FIND(".",(" "&LEFT(SUBSTITUTE(A20,CHAR(13),""),FIND(CHAR(10),SUBSTITUTE(A20,CHAR(13),"")&CHAR(10))-1)))))-LEN(SUBSTITUTE(LEFT((" "&LEFT(SUBSTITUTE(A20,CHAR(13),""),FIND(CHAR(10),SUBSTITUTE(A20,CHAR(13),"")&CHAR(10))-1)),FIND(".",(" "&LEFT(SUBSTITUTE(A20,CHAR(13),""),FIND(CHAR(10),SUBSTITUTE(A20,CHAR(13),"")&CHAR(10))-1))))," ",""))))+1),FIND(" ",(" "&LEFT(SUBSTITUTE(A20,CHAR(13),""),FIND(CHAR(10),SUBSTITUTE(A20,CHAR(13),"")&CHAR(10))-1))&" ",FIND(".",(" "&LEFT(SUBSTITUTE(A20,CHAR(13),""),FIND(CHAR(10),SUBSTITUTE(A20,CHAR(13),"")&CHAR(10))-1))))-(FIND("~",SUBSTITUTE(LEFT((" "&LEFT(SUBSTITUTE(A20,CHAR(13),""),FIND(CHAR(10),SUBSTITUTE(A20,CHAR(13),"")&CHAR(10))-1)),FIND(".",(" "&LEFT(SUBSTITUTE(A20,CHAR(13),""),FIND(CHAR(10),SUBSTITUTE(A20,CHAR(13),"")&CHAR(10))-1))))," ","~",LEN(LEFT((" "&LEFT(SUBSTITUTE(A20,CHAR(13),""),FIND(CHAR(10),SUBSTITUTE(A20,CHAR(13),"")&CHAR(10))-1)),FIND(".",(" "&LEFT(SUBSTITUTE(A20,CHAR(13),""),FIND(CHAR(10),SUBSTITUTE(A20,CHAR(13),"")&CHAR(10))-1)))))-LEN(SUBSTITUTE(LEFT((" "&LEFT(SUBSTITUTE(A20,CHAR(13),""),FIND(CHAR(10),SUBSTITUTE(A20,CHAR(13),"")&CHAR(10))-1)),FIND(".",(" "&LEFT(SUBSTITUTE(A20,CHAR(13),""),FIND(CHAR(10),SUBSTITUTE(A20,CHAR(13),"")&CHAR(10))-1))))," ",""))))+1)),""))
A21: =IFERROR(INDEX(Pegar!$A$3:$A$1002,MATCH(17,Pegar!$B$3:$B$1002,0))&IF(LEFT(INDEX(Pegar!$A$3:$A$1003,MATCH(17,Pegar!$B$3:$B$1002,0)+1),5)="DESC=",CHAR(10)&INDEX(Pegar!$A$3:$A$1003,MATCH(17,Pegar!$B$3:$B$1002,0)+1),""),"") | B21: =IF(TRIM(A21)="","",IFERROR(MID(SUBSTITUTE(SUBSTITUTE(A21,CHAR(10)," "),CHAR(13)," "),FIND(" MT"," "&SUBSTITUTE(SUBSTITUTE(A21,CHAR(10)," "),CHAR(13)," ")),FIND(" ",SUBSTITUTE(SUBSTITUTE(A21,CHAR(10)," "),CHAR(13)," ")&" ",FIND(" MT"," "&SUBSTITUTE(SUBSTITUTE(A21,CHAR(10)," "),CHAR(13)," ")))-FIND(" MT"," "&SUBSTITUTE(SUBSTITUTE(A21,CHAR(10)," "),CHAR(13)," "))),"MT no encontrado")) | C21: =IF(TRIM(A21)="","",IF(D21="",FALSE(),SUBSTITUTE(SUBSTITUTE(SUBSTITUTE(D21,".",""),"0",""),"-","")<>"")) | D21: =IF(TRIM(A21)="","",IFERROR(MID((" "&LEFT(SUBSTITUTE(A21,CHAR(13),""),FIND(CHAR(10),SUBSTITUTE(A21,CHAR(13),"")&CHAR(10))-1)),(FIND("~",SUBSTITUTE(LEFT((" "&LEFT(SUBSTITUTE(A21,CHAR(13),""),FIND(CHAR(10),SUBSTITUTE(A21,CHAR(13),"")&CHAR(10))-1)),FIND(".",(" "&LEFT(SUBSTITUTE(A21,CHAR(13),""),FIND(CHAR(10),SUBSTITUTE(A21,CHAR(13),"")&CHAR(10))-1))))," ","~",LEN(LEFT((" "&LEFT(SUBSTITUTE(A21,CHAR(13),""),FIND(CHAR(10),SUBSTITUTE(A21,CHAR(13),"")&CHAR(10))-1)),FIND(".",(" "&LEFT(SUBSTITUTE(A21,CHAR(13),""),FIND(CHAR(10),SUBSTITUTE(A21,CHAR(13),"")&CHAR(10))-1)))))-LEN(SUBSTITUTE(LEFT((" "&LEFT(SUBSTITUTE(A21,CHAR(13),""),FIND(CHAR(10),SUBSTITUTE(A21,CHAR(13),"")&CHAR(10))-1)),FIND(".",(" "&LEFT(SUBSTITUTE(A21,CHAR(13),""),FIND(CHAR(10),SUBSTITUTE(A21,CHAR(13),"")&CHAR(10))-1))))," ",""))))+1),FIND(" ",(" "&LEFT(SUBSTITUTE(A21,CHAR(13),""),FIND(CHAR(10),SUBSTITUTE(A21,CHAR(13),"")&CHAR(10))-1))&" ",FIND(".",(" "&LEFT(SUBSTITUTE(A21,CHAR(13),""),FIND(CHAR(10),SUBSTITUTE(A21,CHAR(13),"")&CHAR(10))-1))))-(FIND("~",SUBSTITUTE(LEFT((" "&LEFT(SUBSTITUTE(A21,CHAR(13),""),FIND(CHAR(10),SUBSTITUTE(A21,CHAR(13),"")&CHAR(10))-1)),FIND(".",(" "&LEFT(SUBSTITUTE(A21,CHAR(13),""),FIND(CHAR(10),SUBSTITUTE(A21,CHAR(13),"")&CHAR(10))-1))))," ","~",LEN(LEFT((" "&LEFT(SUBSTITUTE(A21,CHAR(13),""),FIND(CHAR(10),SUBSTITUTE(A21,CHAR(13),"")&CHAR(10))-1)),FIND(".",(" "&LEFT(SUBSTITUTE(A21,CHAR(13),""),FIND(CHAR(10),SUBSTITUTE(A21,CHAR(13),"")&CHAR(10))-1)))))-LEN(SUBSTITUTE(LEFT((" "&LEFT(SUBSTITUTE(A21,CHAR(13),""),FIND(CHAR(10),SUBSTITUTE(A21,CHAR(13),"")&CHAR(10))-1)),FIND(".",(" "&LEFT(SUBSTITUTE(A21,CHAR(13),""),FIND(CHAR(10),SUBSTITUTE(A21,CHAR(13),"")&CHAR(10))-1))))," ",""))))+1)),""))
A22: =IFERROR(INDEX(Pegar!$A$3:$A$1002,MATCH(18,Pegar!$B$3:$B$1002,0))&IF(LEFT(INDEX(Pegar!$A$3:$A$1003,MATCH(18,Pegar!$B$3:$B$1002,0)+1),5)="DESC=",CHAR(10)&INDEX(Pegar!$A$3:$A$1003,MATCH(18,Pegar!$B$3:$B$1002,0)+1),""),"") | B22: =IF(TRIM(A22)="","",IFERROR(MID(SUBSTITUTE(SUBSTITUTE(A22,CHAR(10)," "),CHAR(13)," "),FIND(" MT"," "&SUBSTITUTE(SUBSTITUTE(A22,CHAR(10)," "),CHAR(13)," ")),FIND(" ",SUBSTITUTE(SUBSTITUTE(A22,CHAR(10)," "),CHAR(13)," ")&" ",FIND(" MT"," "&SUBSTITUTE(SUBSTITUTE(A22,CHAR(10)," "),CHAR(13)," ")))-FIND(" MT"," "&SUBSTITUTE(SUBSTITUTE(A22,CHAR(10)," "),CHAR(13)," "))),"MT no encontrado")) | C22: =IF(TRIM(A22)="","",IF(D22="",FALSE(),SUBSTITUTE(SUBSTITUTE(SUBSTITUTE(D22,".",""),"0",""),"-","")<>"")) | D22: =IF(TRIM(A22)="","",IFERROR(MID((" "&LEFT(SUBSTITUTE(A22,CHAR(13),""),FIND(CHAR(10),SUBSTITUTE(A22,CHAR(13),"")&CHAR(10))-1)),(FIND("~",SUBSTITUTE(LEFT((" "&LEFT(SUBSTITUTE(A22,CHAR(13),""),FIND(CHAR(10),SUBSTITUTE(A22,CHAR(13),"")&CHAR(10))-1)),FIND(".",(" "&LEFT(SUBSTITUTE(A22,CHAR(13),""),FIND(CHAR(10),SUBSTITUTE(A22,CHAR(13),"")&CHAR(10))-1))))," ","~",LEN(LEFT((" "&LEFT(SUBSTITUTE(A22,CHAR(13),""),FIND(CHAR(10),SUBSTITUTE(A22,CHAR(13),"")&CHAR(10))-1)),FIND(".",(" "&LEFT(SUBSTITUTE(A22,CHAR(13),""),FIND(CHAR(10),SUBSTITUTE(A22,CHAR(13),"")&CHAR(10))-1)))))-LEN(SUBSTITUTE(LEFT((" "&LEFT(SUBSTITUTE(A22,CHAR(13),""),FIND(CHAR(10),SUBSTITUTE(A22,CHAR(13),"")&CHAR(10))-1)),FIND(".",(" "&LEFT(SUBSTITUTE(A22,CHAR(13),""),FIND(CHAR(10),SUBSTITUTE(A22,CHAR(13),"")&CHAR(10))-1))))," ",""))))+1),FIND(" ",(" "&LEFT(SUBSTITUTE(A22,CHAR(13),""),FIND(CHAR(10),SUBSTITUTE(A22,CHAR(13),"")&CHAR(10))-1))&" ",FIND(".",(" "&LEFT(SUBSTITUTE(A22,CHAR(13),""),FIND(CHAR(10),SUBSTITUTE(A22,CHAR(13),"")&CHAR(10))-1))))-(FIND("~",SUBSTITUTE(LEFT((" "&LEFT(SUBSTITUTE(A22,CHAR(13),""),FIND(CHAR(10),SUBSTITUTE(A22,CHAR(13),"")&CHAR(10))-1)),FIND(".",(" "&LEFT(SUBSTITUTE(A22,CHAR(13),""),FIND(CHAR(10),SUBSTITUTE(A22,CHAR(13),"")&CHAR(10))-1))))," ","~",LEN(LEFT((" "&LEFT(SUBSTITUTE(A22,CHAR(13),""),FIND(CHAR(10),SUBSTITUTE(A22,CHAR(13),"")&CHAR(10))-1)),FIND(".",(" "&LEFT(SUBSTITUTE(A22,CHAR(13),""),FIND(CHAR(10),SUBSTITUTE(A22,CHAR(13),"")&CHAR(10))-1)))))-LEN(SUBSTITUTE(LEFT((" "&LEFT(SUBSTITUTE(A22,CHAR(13),""),FIND(CHAR(10),SUBSTITUTE(A22,CHAR(13),"")&CHAR(10))-1)),FIND(".",(" "&LEFT(SUBSTITUTE(A22,CHAR(13),""),FIND(CHAR(10),SUBSTITUTE(A22,CHAR(13),"")&CHAR(10))-1))))," ",""))))+1)),""))
A23: =IFERROR(INDEX(Pegar!$A$3:$A$1002,MATCH(19,Pegar!$B$3:$B$1002,0))&IF(LEFT(INDEX(Pegar!$A$3:$A$1003,MATCH(19,Pegar!$B$3:$B$1002,0)+1),5)="DESC=",CHAR(10)&INDEX(Pegar!$A$3:$A$1003,MATCH(19,Pegar!$B$3:$B$1002,0)+1),""),"") | B23: =IF(TRIM(A23)="","",IFERROR(MID(SUBSTITUTE(SUBSTITUTE(A23,CHAR(10)," "),CHAR(13)," "),FIND(" MT"," "&SUBSTITUTE(SUBSTITUTE(A23,CHAR(10)," "),CHAR(13)," ")),FIND(" ",SUBSTITUTE(SUBSTITUTE(A23,CHAR(10)," "),CHAR(13)," ")&" ",FIND(" MT"," "&SUBSTITUTE(SUBSTITUTE(A23,CHAR(10)," "),CHAR(13)," ")))-FIND(" MT"," "&SUBSTITUTE(SUBSTITUTE(A23,CHAR(10)," "),CHAR(13)," "))),"MT no encontrado")) | C23: =IF(TRIM(A23)="","",IF(D23="",FALSE(),SUBSTITUTE(SUBSTITUTE(SUBSTITUTE(D23,".",""),"0",""),"-","")<>"")) | D23: =IF(TRIM(A23)="","",IFERROR(MID((" "&LEFT(SUBSTITUTE(A23,CHAR(13),""),FIND(CHAR(10),SUBSTITUTE(A23,CHAR(13),"")&CHAR(10))-1)),(FIND("~",SUBSTITUTE(LEFT((" "&LEFT(SUBSTITUTE(A23,CHAR(13),""),FIND(CHAR(10),SUBSTITUTE(A23,CHAR(13),"")&CHAR(10))-1)),FIND(".",(" "&LEFT(SUBSTITUTE(A23,CHAR(13),""),FIND(CHAR(10),SUBSTITUTE(A23,CHAR(13),"")&CHAR(10))-1))))," ","~",LEN(LEFT((" "&LEFT(SUBSTITUTE(A23,CHAR(13),""),FIND(CHAR(10),SUBSTITUTE(A23,CHAR(13),"")&CHAR(10))-1)),FIND(".",(" "&LEFT(SUBSTITUTE(A23,CHAR(13),""),FIND(CHAR(10),SUBSTITUTE(A23,CHAR(13),"")&CHAR(10))-1)))))-LEN(SUBSTITUTE(LEFT((" "&LEFT(SUBSTITUTE(A23,CHAR(13),""),FIND(CHAR(10),SUBSTITUTE(A23,CHAR(13),"")&CHAR(10))-1)),FIND(".",(" "&LEFT(SUBSTITUTE(A23,CHAR(13),""),FIND(CHAR(10),SUBSTITUTE(A23,CHAR(13),"")&CHAR(10))-1))))," ",""))))+1),FIND(" ",(" "&LEFT(SUBSTITUTE(A23,CHAR(13),""),FIND(CHAR(10),SUBSTITUTE(A23,CHAR(13),"")&CHAR(10))-1))&" ",FIND(".",(" "&LEFT(SUBSTITUTE(A23,CHAR(13),""),FIND(CHAR(10),SUBSTITUTE(A23,CHAR(13),"")&CHAR(10))-1))))-(FIND("~",SUBSTITUTE(LEFT((" "&LEFT(SUBSTITUTE(A23,CHAR(13),""),FIND(CHAR(10),SUBSTITUTE(A23,CHAR(13),"")&CHAR(10))-1)),FIND(".",(" "&LEFT(SUBSTITUTE(A23,CHAR(13),""),FIND(CHAR(10),SUBSTITUTE(A23,CHAR(13),"")&CHAR(10))-1))))," ","~",LEN(LEFT((" "&LEFT(SUBSTITUTE(A23,CHAR(13),""),FIND(CHAR(10),SUBSTITUTE(A23,CHAR(13),"")&CHAR(10))-1)),FIND(".",(" "&LEFT(SUBSTITUTE(A23,CHAR(13),""),FIND(CHAR(10),SUBSTITUTE(A23,CHAR(13),"")&CHAR(10))-1)))))-LEN(SUBSTITUTE(LEFT((" "&LEFT(SUBSTITUTE(A23,CHAR(13),""),FIND(CHAR(10),SUBSTITUTE(A23,CHAR(13),"")&CHAR(10))-1)),FIND(".",(" "&LEFT(SUBSTITUTE(A23,CHAR(13),""),FIND(CHAR(10),SUBSTITUTE(A23,CHAR(13),"")&CHAR(10))-1))))," ",""))))+1)),""))
A24: =IFERROR(INDEX(Pegar!$A$3:$A$1002,MATCH(20,Pegar!$B$3:$B$1002,0))&IF(LEFT(INDEX(Pegar!$A$3:$A$1003,MATCH(20,Pegar!$B$3:$B$1002,0)+1),5)="DESC=",CHAR(10)&INDEX(Pegar!$A$3:$A$1003,MATCH(20,Pegar!$B$3:$B$1002,0)+1),""),"") | B24: =IF(TRIM(A24)="","",IFERROR(MID(SUBSTITUTE(SUBSTITUTE(A24,CHAR(10)," "),CHAR(13)," "),FIND(" MT"," "&SUBSTITUTE(SUBSTITUTE(A24,CHAR(10)," "),CHAR(13)," ")),FIND(" ",SUBSTITUTE(SUBSTITUTE(A24,CHAR(10)," "),CHAR(13)," ")&" ",FIND(" MT"," "&SUBSTITUTE(SUBSTITUTE(A24,CHAR(10)," "),CHAR(13)," ")))-FIND(" MT"," "&SUBSTITUTE(SUBSTITUTE(A24,CHAR(10)," "),CHAR(13)," "))),"MT no encontrado")) | C24: =IF(TRIM(A24)="","",IF(D24="",FALSE(),SUBSTITUTE(SUBSTITUTE(SUBSTITUTE(D24,".",""),"0",""),"-","")<>"")) | D24: =IF(TRIM(A24)="","",IFERROR(MID((" "&LEFT(SUBSTITUTE(A24,CHAR(13),""),FIND(CHAR(10),SUBSTITUTE(A24,CHAR(13),"")&CHAR(10))-1)),(FIND("~",SUBSTITUTE(LEFT((" "&LEFT(SUBSTITUTE(A24,CHAR(13),""),FIND(CHAR(10),SUBSTITUTE(A24,CHAR(13),"")&CHAR(10))-1)),FIND(".",(" "&LEFT(SUBSTITUTE(A24,CHAR(13),""),FIND(CHAR(10),SUBSTITUTE(A24,CHAR(13),"")&CHAR(10))-1))))," ","~",LEN(LEFT((" "&LEFT(SUBSTITUTE(A24,CHAR(13),""),FIND(CHAR(10),SUBSTITUTE(A24,CHAR(13),"")&CHAR(10))-1)),FIND(".",(" "&LEFT(SUBSTITUTE(A24,CHAR(13),""),FIND(CHAR(10),SUBSTITUTE(A24,CHAR(13),"")&CHAR(10))-1)))))-LEN(SUBSTITUTE(LEFT((" "&LEFT(SUBSTITUTE(A24,CHAR(13),""),FIND(CHAR(10),SUBSTITUTE(A24,CHAR(13),"")&CHAR(10))-1)),FIND(".",(" "&LEFT(SUBSTITUTE(A24,CHAR(13),""),FIND(CHAR(10),SUBSTITUTE(A24,CHAR(13),"")&CHAR(10))-1))))," ",""))))+1),FIND(" ",(" "&LEFT(SUBSTITUTE(A24,CHAR(13),""),FIND(CHAR(10),SUBSTITUTE(A24,CHAR(13),"")&CHAR(10))-1))&" ",FIND(".",(" "&LEFT(SUBSTITUTE(A24,CHAR(13),""),FIND(CHAR(10),SUBSTITUTE(A24,CHAR(13),"")&CHAR(10))-1))))-(FIND("~",SUBSTITUTE(LEFT((" "&LEFT(SUBSTITUTE(A24,CHAR(13),""),FIND(CHAR(10),SUBSTITUTE(A24,CHAR(13),"")&CHAR(10))-1)),FIND(".",(" "&LEFT(SUBSTITUTE(A24,CHAR(13),""),FIND(CHAR(10),SUBSTITUTE(A24,CHAR(13),"")&CHAR(10))-1))))," ","~",LEN(LEFT((" "&LEFT(SUBSTITUTE(A24,CHAR(13),""),FIND(CHAR(10),SUBSTITUTE(A24,CHAR(13),"")&CHAR(10))-1)),FIND(".",(" "&LEFT(SUBSTITUTE(A24,CHAR(13),""),FIND(CHAR(10),SUBSTITUTE(A24,CHAR(13),"")&CHAR(10))-1)))))-LEN(SUBSTITUTE(LEFT((" "&LEFT(SUBSTITUTE(A24,CHAR(13),""),FIND(CHAR(10),SUBSTITUTE(A24,CHAR(13),"")&CHAR(10))-1)),FIND(".",(" "&LEFT(SUBSTITUTE(A24,CHAR(13),""),FIND(CHAR(10),SUBSTITUTE(A24,CHAR(13),"")&CHAR(10))-1))))," ",""))))+1)),""))
A25: =IFERROR(INDEX(Pegar!$A$3:$A$1002,MATCH(21,Pegar!$B$3:$B$1002,0))&IF(LEFT(INDEX(Pegar!$A$3:$A$1003,MATCH(21,Pegar!$B$3:$B$1002,0)+1),5)="DESC=",CHAR(10)&INDEX(Pegar!$A$3:$A$1003,MATCH(21,Pegar!$B$3:$B$1002,0)+1),""),"") | B25: =IF(TRIM(A25)="","",IFERROR(MID(SUBSTITUTE(SUBSTITUTE(A25,CHAR(10)," "),CHAR(13)," "),FIND(" MT"," "&SUBSTITUTE(SUBSTITUTE(A25,CHAR(10)," "),CHAR(13)," ")),FIND(" ",SUBSTITUTE(SUBSTITUTE(A25,CHAR(10)," "),CHAR(13)," ")&" ",FIND(" MT"," "&SUBSTITUTE(SUBSTITUTE(A25,CHAR(10)," "),CHAR(13)," ")))-FIND(" MT"," "&SUBSTITUTE(SUBSTITUTE(A25,CHAR(10)," "),CHAR(13)," "))),"MT no encontrado")) | C25: =IF(TRIM(A25)="","",IF(D25="",FALSE(),SUBSTITUTE(SUBSTITUTE(SUBSTITUTE(D25,".",""),"0",""),"-","")<>"")) | D25: =IF(TRIM(A25)="","",IFERROR(MID((" "&LEFT(SUBSTITUTE(A25,CHAR(13),""),FIND(CHAR(10),SUBSTITUTE(A25,CHAR(13),"")&CHAR(10))-1)),(FIND("~",SUBSTITUTE(LEFT((" "&LEFT(SUBSTITUTE(A25,CHAR(13),""),FIND(CHAR(10),SUBSTITUTE(A25,CHAR(13),"")&CHAR(10))-1)),FIND(".",(" "&LEFT(SUBSTITUTE(A25,CHAR(13),""),FIND(CHAR(10),SUBSTITUTE(A25,CHAR(13),"")&CHAR(10))-1))))," ","~",LEN(LEFT((" "&LEFT(SUBSTITUTE(A25,CHAR(13),""),FIND(CHAR(10),SUBSTITUTE(A25,CHAR(13),"")&CHAR(10))-1)),FIND(".",(" "&LEFT(SUBSTITUTE(A25,CHAR(13),""),FIND(CHAR(10),SUBSTITUTE(A25,CHAR(13),"")&CHAR(10))-1)))))-LEN(SUBSTITUTE(LEFT((" "&LEFT(SUBSTITUTE(A25,CHAR(13),""),FIND(CHAR(10),SUBSTITUTE(A25,CHAR(13),"")&CHAR(10))-1)),FIND(".",(" "&LEFT(SUBSTITUTE(A25,CHAR(13),""),FIND(CHAR(10),SUBSTITUTE(A25,CHAR(13),"")&CHAR(10))-1))))," ",""))))+1),FIND(" ",(" "&LEFT(SUBSTITUTE(A25,CHAR(13),""),FIND(CHAR(10),SUBSTITUTE(A25,CHAR(13),"")&CHAR(10))-1))&" ",FIND(".",(" "&LEFT(SUBSTITUTE(A25,CHAR(13),""),FIND(CHAR(10),SUBSTITUTE(A25,CHAR(13),"")&CHAR(10))-1))))-(FIND("~",SUBSTITUTE(LEFT((" "&LEFT(SUBSTITUTE(A25,CHAR(13),""),FIND(CHAR(10),SUBSTITUTE(A25,CHAR(13),"")&CHAR(10))-1)),FIND(".",(" "&LEFT(SUBSTITUTE(A25,CHAR(13),""),FIND(CHAR(10),SUBSTITUTE(A25,CHAR(13),"")&CHAR(10))-1))))," ","~",LEN(LEFT((" "&LEFT(SUBSTITUTE(A25,CHAR(13),""),FIND(CHAR(10),SUBSTITUTE(A25,CHAR(13),"")&CHAR(10))-1)),FIND(".",(" "&LEFT(SUBSTITUTE(A25,CHAR(13),""),FIND(CHAR(10),SUBSTITUTE(A25,CHAR(13),"")&CHAR(10))-1)))))-LEN(SUBSTITUTE(LEFT((" "&LEFT(SUBSTITUTE(A25,CHAR(13),""),FIND(CHAR(10),SUBSTITUTE(A25,CHAR(13),"")&CHAR(10))-1)),FIND(".",(" "&LEFT(SUBSTITUTE(A25,CHAR(13),""),FIND(CHAR(10),SUBSTITUTE(A25,CHAR(13),"")&CHAR(10))-1))))," ",""))))+1)),""))
A26: =IFERROR(INDEX(Pegar!$A$3:$A$1002,MATCH(22,Pegar!$B$3:$B$1002,0))&IF(LEFT(INDEX(Pegar!$A$3:$A$1003,MATCH(22,Pegar!$B$3:$B$1002,0)+1),5)="DESC=",CHAR(10)&INDEX(Pegar!$A$3:$A$1003,MATCH(22,Pegar!$B$3:$B$1002,0)+1),""),"") | B26: =IF(TRIM(A26)="","",IFERROR(MID(SUBSTITUTE(SUBSTITUTE(A26,CHAR(10)," "),CHAR(13)," "),FIND(" MT"," "&SUBSTITUTE(SUBSTITUTE(A26,CHAR(10)," "),CHAR(13)," ")),FIND(" ",SUBSTITUTE(SUBSTITUTE(A26,CHAR(10)," "),CHAR(13)," ")&" ",FIND(" MT"," "&SUBSTITUTE(SUBSTITUTE(A26,CHAR(10)," "),CHAR(13)," ")))-FIND(" MT"," "&SUBSTITUTE(SUBSTITUTE(A26,CHAR(10)," "),CHAR(13)," "))),"MT no encontrado")) | C26: =IF(TRIM(A26)="","",IF(D26="",FALSE(),SUBSTITUTE(SUBSTITUTE(SUBSTITUTE(D26,".",""),"0",""),"-","")<>"")) | D26: =IF(TRIM(A26)="","",IFERROR(MID((" "&LEFT(SUBSTITUTE(A26,CHAR(13),""),FIND(CHAR(10),SUBSTITUTE(A26,CHAR(13),"")&CHAR(10))-1)),(FIND("~",SUBSTITUTE(LEFT((" "&LEFT(SUBSTITUTE(A26,CHAR(13),""),FIND(CHAR(10),SUBSTITUTE(A26,CHAR(13),"")&CHAR(10))-1)),FIND(".",(" "&LEFT(SUBSTITUTE(A26,CHAR(13),""),FIND(CHAR(10),SUBSTITUTE(A26,CHAR(13),"")&CHAR(10))-1))))," ","~",LEN(LEFT((" "&LEFT(SUBSTITUTE(A26,CHAR(13),""),FIND(CHAR(10),SUBSTITUTE(A26,CHAR(13),"")&CHAR(10))-1)),FIND(".",(" "&LEFT(SUBSTITUTE(A26,CHAR(13),""),FIND(CHAR(10),SUBSTITUTE(A26,CHAR(13),"")&CHAR(10))-1)))))-LEN(SUBSTITUTE(LEFT((" "&LEFT(SUBSTITUTE(A26,CHAR(13),""),FIND(CHAR(10),SUBSTITUTE(A26,CHAR(13),"")&CHAR(10))-1)),FIND(".",(" "&LEFT(SUBSTITUTE(A26,CHAR(13),""),FIND(CHAR(10),SUBSTITUTE(A26,CHAR(13),"")&CHAR(10))-1))))," ",""))))+1),FIND(" ",(" "&LEFT(SUBSTITUTE(A26,CHAR(13),""),FIND(CHAR(10),SUBSTITUTE(A26,CHAR(13),"")&CHAR(10))-1))&" ",FIND(".",(" "&LEFT(SUBSTITUTE(A26,CHAR(13),""),FIND(CHAR(10),SUBSTITUTE(A26,CHAR(13),"")&CHAR(10))-1))))-(FIND("~",SUBSTITUTE(LEFT((" "&LEFT(SUBSTITUTE(A26,CHAR(13),""),FIND(CHAR(10),SUBSTITUTE(A26,CHAR(13),"")&CHAR(10))-1)),FIND(".",(" "&LEFT(SUBSTITUTE(A26,CHAR(13),""),FIND(CHAR(10),SUBSTITUTE(A26,CHAR(13),"")&CHAR(10))-1))))," ","~",LEN(LEFT((" "&LEFT(SUBSTITUTE(A26,CHAR(13),""),FIND(CHAR(10),SUBSTITUTE(A26,CHAR(13),"")&CHAR(10))-1)),FIND(".",(" "&LEFT(SUBSTITUTE(A26,CHAR(13),""),FIND(CHAR(10),SUBSTITUTE(A26,CHAR(13),"")&CHAR(10))-1)))))-LEN(SUBSTITUTE(LEFT((" "&LEFT(SUBSTITUTE(A26,CHAR(13),""),FIND(CHAR(10),SUBSTITUTE(A26,CHAR(13),"")&CHAR(10))-1)),FIND(".",(" "&LEFT(SUBSTITUTE(A26,CHAR(13),""),FIND(CHAR(10),SUBSTITUTE(A26,CHAR(13),"")&CHAR(10))-1))))," ",""))))+1)),""))
A27: =IFERROR(INDEX(Pegar!$A$3:$A$1002,MATCH(23,Pegar!$B$3:$B$1002,0))&IF(LEFT(INDEX(Pegar!$A$3:$A$1003,MATCH(23,Pegar!$B$3:$B$1002,0)+1),5)="DESC=",CHAR(10)&INDEX(Pegar!$A$3:$A$1003,MATCH(23,Pegar!$B$3:$B$1002,0)+1),""),"") | B27: =IF(TRIM(A27)="","",IFERROR(MID(SUBSTITUTE(SUBSTITUTE(A27,CHAR(10)," "),CHAR(13)," "),FIND(" MT"," "&SUBSTITUTE(SUBSTITUTE(A27,CHAR(10)," "),CHAR(13)," ")),FIND(" ",SUBSTITUTE(SUBSTITUTE(A27,CHAR(10)," "),CHAR(13)," ")&" ",FIND(" MT"," "&SUBSTITUTE(SUBSTITUTE(A27,CHAR(10)," "),CHAR(13)," ")))-FIND(" MT"," "&SUBSTITUTE(SUBSTITUTE(A27,CHAR(10)," "),CHAR(13)," "))),"MT no encontrado")) | C27: =IF(TRIM(A27)="","",IF(D27="",FALSE(),SUBSTITUTE(SUBSTITUTE(SUBSTITUTE(D27,".",""),"0",""),"-","")<>"")) | D27: =IF(TRIM(A27)="","",IFERROR(MID((" "&LEFT(SUBSTITUTE(A27,CHAR(13),""),FIND(CHAR(10),SUBSTITUTE(A27,CHAR(13),"")&CHAR(10))-1)),(FIND("~",SUBSTITUTE(LEFT((" "&LEFT(SUBSTITUTE(A27,CHAR(13),""),FIND(CHAR(10),SUBSTITUTE(A27,CHAR(13),"")&CHAR(10))-1)),FIND(".",(" "&LEFT(SUBSTITUTE(A27,CHAR(13),""),FIND(CHAR(10),SUBSTITUTE(A27,CHAR(13),"")&CHAR(10))-1))))," ","~",LEN(LEFT((" "&LEFT(SUBSTITUTE(A27,CHAR(13),""),FIND(CHAR(10),SUBSTITUTE(A27,CHAR(13),"")&CHAR(10))-1)),FIND(".",(" "&LEFT(SUBSTITUTE(A27,CHAR(13),""),FIND(CHAR(10),SUBSTITUTE(A27,CHAR(13),"")&CHAR(10))-1)))))-LEN(SUBSTITUTE(LEFT((" "&LEFT(SUBSTITUTE(A27,CHAR(13),""),FIND(CHAR(10),SUBSTITUTE(A27,CHAR(13),"")&CHAR(10))-1)),FIND(".",(" "&LEFT(SUBSTITUTE(A27,CHAR(13),""),FIND(CHAR(10),SUBSTITUTE(A27,CHAR(13),"")&CHAR(10))-1))))," ",""))))+1),FIND(" ",(" "&LEFT(SUBSTITUTE(A27,CHAR(13),""),FIND(CHAR(10),SUBSTITUTE(A27,CHAR(13),"")&CHAR(10))-1))&" ",FIND(".",(" "&LEFT(SUBSTITUTE(A27,CHAR(13),""),FIND(CHAR(10),SUBSTITUTE(A27,CHAR(13),"")&CHAR(10))-1))))-(FIND("~",SUBSTITUTE(LEFT((" "&LEFT(SUBSTITUTE(A27,CHAR(13),""),FIND(CHAR(10),SUBSTITUTE(A27,CHAR(13),"")&CHAR(10))-1)),FIND(".",(" "&LEFT(SUBSTITUTE(A27,CHAR(13),""),FIND(CHAR(10),SUBSTITUTE(A27,CHAR(13),"")&CHAR(10))-1))))," ","~",LEN(LEFT((" "&LEFT(SUBSTITUTE(A27,CHAR(13),""),FIND(CHAR(10),SUBSTITUTE(A27,CHAR(13),"")&CHAR(10))-1)),FIND(".",(" "&LEFT(SUBSTITUTE(A27,CHAR(13),""),FIND(CHAR(10),SUBSTITUTE(A27,CHAR(13),"")&CHAR(10))-1)))))-LEN(SUBSTITUTE(LEFT((" "&LEFT(SUBSTITUTE(A27,CHAR(13),""),FIND(CHAR(10),SUBSTITUTE(A27,CHAR(13),"")&CHAR(10))-1)),FIND(".",(" "&LEFT(SUBSTITUTE(A27,CHAR(13),""),FIND(CHAR(10),SUBSTITUTE(A27,CHAR(13),"")&CHAR(10))-1))))," ",""))))+1)),""))
